2024-02-10 17:06:09.781 | ERROR    | __main__:parse_data:87 - error
Traceback (most recent call last):

  File "/mnt/E83C5EC13C5E8A88/projects/etagi/.venv/lib/python3.11/site-packages/socks.py", line 787, in connect
    super(socksocket, self).connect(proxy_addr)
          │           │             └ 'localhost'
          │           └ <socks.socksocket [closed] fd=-1, family=2, type=1, proto=6>
          └ <class 'socks.socksocket'>

ConnectionRefusedError: [Errno 111] Connection refused


During handling of the above exception, another exception occurred:


Traceback (most recent call last):

  File "/mnt/E83C5EC13C5E8A88/projects/etagi/.venv/lib/python3.11/site-packages/urllib3/connection.py", line 198, in _new_conn
    sock = connection.create_connection(
           │          └ <function create_connection at 0x7fb0cdb854e0>
           └ <module 'urllib3.util.connection' from '/mnt/E83C5EC13C5E8A88/projects/etagi/.venv/lib/python3.11/site-packages/urllib3/util/...
  File "/mnt/E83C5EC13C5E8A88/projects/etagi/.venv/lib/python3.11/site-packages/urllib3/util/connection.py", line 85, in create_connection
    raise err
          └ None
  File "/mnt/E83C5EC13C5E8A88/projects/etagi/.venv/lib/python3.11/site-packages/urllib3/util/connection.py", line 73, in create_connection
    sock.connect(sa)
    │    │       └ ('185.143.129.89', 443)
    │    └ <function socksocket.connect at 0x7fb0ccfac860>
    └ <socks.socksocket [closed] fd=-1, family=2, type=1, proto=6>
  File "/mnt/E83C5EC13C5E8A88/projects/etagi/.venv/lib/python3.11/site-packages/socks.py", line 47, in wrapper
    return function(*args, **kwargs)
           │         │       └ {}
           │         └ (<socks.socksocket [closed] fd=-1, family=2, type=1, proto=6>, ('185.143.129.89', 443))
           └ <function socksocket.connect at 0x7fb0ccfac7c0>
  File "/mnt/E83C5EC13C5E8A88/projects/etagi/.venv/lib/python3.11/site-packages/socks.py", line 800, in connect
    raise ProxyConnectionError(msg, error)
          │                    └ 'Error connecting to SOCKS5 proxy localhost:9150'
          └ <class 'socks.ProxyConnectionError'>

socks.ProxyConnectionError: Error connecting to SOCKS5 proxy localhost:9150: [Errno 111] Connection refused


The above exception was the direct cause of the following exception:


Traceback (most recent call last):

  File "/mnt/E83C5EC13C5E8A88/projects/etagi/.venv/lib/python3.11/site-packages/urllib3/connectionpool.py", line 793, in urlopen
    response = self._make_request(
               │    └ <function HTTPConnectionPool._make_request at 0x7fb0cd3b8fe0>
               └ <urllib3.connectionpool.HTTPSConnectionPool object at 0x7fb0cb9b6290>
  File "/mnt/E83C5EC13C5E8A88/projects/etagi/.venv/lib/python3.11/site-packages/urllib3/connectionpool.py", line 491, in _make_request
    raise new_e
          └ NewConnectionError('<urllib3.connection.HTTPSConnection object at 0x7fb0cb9b7e90>: Failed to establish a new connection: Erro...
  File "/mnt/E83C5EC13C5E8A88/projects/etagi/.venv/lib/python3.11/site-packages/urllib3/connectionpool.py", line 467, in _make_request
    self._validate_conn(conn)
    │    │              └ <urllib3.connection.HTTPSConnection object at 0x7fb0cb9b7e90>
    │    └ <function HTTPSConnectionPool._validate_conn at 0x7fb0cd3b9580>
    └ <urllib3.connectionpool.HTTPSConnectionPool object at 0x7fb0cb9b6290>
  File "/mnt/E83C5EC13C5E8A88/projects/etagi/.venv/lib/python3.11/site-packages/urllib3/connectionpool.py", line 1099, in _validate_conn
    conn.connect()
    │    └ <function HTTPSConnection.connect at 0x7fb0cd3a1260>
    └ <urllib3.connection.HTTPSConnection object at 0x7fb0cb9b7e90>
  File "/mnt/E83C5EC13C5E8A88/projects/etagi/.venv/lib/python3.11/site-packages/urllib3/connection.py", line 616, in connect
    self.sock = sock = self._new_conn()
    │    │             │    └ <function HTTPConnection._new_conn at 0x7fb0cd3a0900>
    │    │             └ <urllib3.connection.HTTPSConnection object at 0x7fb0cb9b7e90>
    │    └ None
    └ <urllib3.connection.HTTPSConnection object at 0x7fb0cb9b7e90>
  File "/mnt/E83C5EC13C5E8A88/projects/etagi/.venv/lib/python3.11/site-packages/urllib3/connection.py", line 213, in _new_conn
    raise NewConnectionError(
          └ <class 'urllib3.exceptions.NewConnectionError'>

urllib3.exceptions.NewConnectionError: <urllib3.connection.HTTPSConnection object at 0x7fb0cb9b7e90>: Failed to establish a new connection: Error connecting to SOCKS5 proxy localhost:9150: [Errno 111] Connection refused


The above exception was the direct cause of the following exception:


Traceback (most recent call last):

  File "/mnt/E83C5EC13C5E8A88/projects/etagi/.venv/lib/python3.11/site-packages/requests/adapters.py", line 486, in send
    resp = conn.urlopen(
           │    └ <function HTTPConnectionPool.urlopen at 0x7fb0cd3b91c0>
           └ <urllib3.connectionpool.HTTPSConnectionPool object at 0x7fb0cb9b6290>
  File "/mnt/E83C5EC13C5E8A88/projects/etagi/.venv/lib/python3.11/site-packages/urllib3/connectionpool.py", line 847, in urlopen
    retries = retries.increment(
              │       └ <function Retry.increment at 0x7fb0cd318040>
              └ Retry(total=0, connect=None, read=False, redirect=None, status=None)
  File "/mnt/E83C5EC13C5E8A88/projects/etagi/.venv/lib/python3.11/site-packages/urllib3/util/retry.py", line 515, in increment
    raise MaxRetryError(_pool, url, reason) from reason  # type: ignore[arg-type]
          │             │      │    │            └ NewConnectionError('<urllib3.connection.HTTPSConnection object at 0x7fb0cb9b7e90>: Failed to establish a new connection: Erro...
          │             │      │    └ NewConnectionError('<urllib3.connection.HTTPSConnection object at 0x7fb0cb9b7e90>: Failed to establish a new connection: Erro...
          │             │      └ '/a/ajaxGetSearchNbResults?search-url=/arenda/kvartiry/almaty/?das%5Bmap.complex%5D=1&isOnMap=0'
          │             └ <urllib3.connectionpool.HTTPSConnectionPool object at 0x7fb0cb9b6290>
          └ <class 'urllib3.exceptions.MaxRetryError'>

urllib3.exceptions.MaxRetryError: HTTPSConnectionPool(host='krisha.kz', port=443): Max retries exceeded with url: /a/ajaxGetSearchNbResults?search-url=/arenda/kvartiry/almaty/?das%5Bmap.complex%5D=1&isOnMap=0 (Caused by NewConnectionError('<urllib3.connection.HTTPSConnection object at 0x7fb0cb9b7e90>: Failed to establish a new connection: Error connecting to SOCKS5 proxy localhost:9150: [Errno 111] Connection refused'))


During handling of the above exception, another exception occurred:


Traceback (most recent call last):

  File "/mnt/E83C5EC13C5E8A88/projects/etagi/nb_parser.py", line 92, in <module>
    parse_data()
    └ <function parse_data at 0x7fb0cb979bc0>

> File "/mnt/E83C5EC13C5E8A88/projects/etagi/nb_parser.py", line 61, in parse_data
    r = requests.get(url=querry.format(str(i)), headers=headers)
        │        │       │      │          │            └ {'Host': 'krisha.kz', 'User-Agent': 'Mozilla/5.0 (X11; Ubuntu; Linux x86_64; rv:109.0) Gecko/20100101 Firefox/119.0', 'Accept...
        │        │       │      │          └ 1
        │        │       │      └ <method 'format' of 'str' objects>
        │        │       └ 'https://krisha.kz/a/ajaxGetSearchNbResults?search-url=/arenda/kvartiry/almaty/?das[map.complex]={}&isOnMap=0'
        │        └ <function get at 0x7fb0ccf42ac0>
        └ <module 'requests' from '/mnt/E83C5EC13C5E8A88/projects/etagi/.venv/lib/python3.11/site-packages/requests/__init__.py'>

  File "/mnt/E83C5EC13C5E8A88/projects/etagi/.venv/lib/python3.11/site-packages/requests/api.py", line 73, in get
    return request("get", url, params=params, **kwargs)
           │              │           │         └ {'headers': {'Host': 'krisha.kz', 'User-Agent': 'Mozilla/5.0 (X11; Ubuntu; Linux x86_64; rv:109.0) Gecko/20100101 Firefox/119...
           │              │           └ None
           │              └ 'https://krisha.kz/a/ajaxGetSearchNbResults?search-url=/arenda/kvartiry/almaty/?das[map.complex]=1&isOnMap=0'
           └ <function request at 0x7fb0ccf59bc0>
  File "/mnt/E83C5EC13C5E8A88/projects/etagi/.venv/lib/python3.11/site-packages/requests/api.py", line 59, in request
    return session.request(method=method, url=url, **kwargs)
           │       │              │           │      └ {'params': None, 'headers': {'Host': 'krisha.kz', 'User-Agent': 'Mozilla/5.0 (X11; Ubuntu; Linux x86_64; rv:109.0) Gecko/2010...
           │       │              │           └ 'https://krisha.kz/a/ajaxGetSearchNbResults?search-url=/arenda/kvartiry/almaty/?das[map.complex]=1&isOnMap=0'
           │       │              └ 'get'
           │       └ <function Session.request at 0x7fb0ccfadd00>
           └ <requests.sessions.Session object at 0x7fb0cbdd2610>
  File "/mnt/E83C5EC13C5E8A88/projects/etagi/.venv/lib/python3.11/site-packages/requests/sessions.py", line 589, in request
    resp = self.send(prep, **send_kwargs)
           │    │    │       └ {'timeout': None, 'allow_redirects': True, 'proxies': OrderedDict(), 'stream': False, 'verify': True, 'cert': None}
           │    │    └ <PreparedRequest [GET]>
           │    └ <function Session.send at 0x7fb0ccfae200>
           └ <requests.sessions.Session object at 0x7fb0cbdd2610>
  File "/mnt/E83C5EC13C5E8A88/projects/etagi/.venv/lib/python3.11/site-packages/requests/sessions.py", line 703, in send
    r = adapter.send(request, **kwargs)
        │       │    │          └ {'timeout': None, 'proxies': OrderedDict(), 'stream': False, 'verify': True, 'cert': None}
        │       │    └ <PreparedRequest [GET]>
        │       └ <function HTTPAdapter.send at 0x7fb0ccfad580>
        └ <requests.adapters.HTTPAdapter object at 0x7fb0cbde0a50>
  File "/mnt/E83C5EC13C5E8A88/projects/etagi/.venv/lib/python3.11/site-packages/requests/adapters.py", line 519, in send
    raise ConnectionError(e, request=request)
          │                          └ <PreparedRequest [GET]>
          └ <class 'requests.exceptions.ConnectionError'>

requests.exceptions.ConnectionError: HTTPSConnectionPool(host='krisha.kz', port=443): Max retries exceeded with url: /a/ajaxGetSearchNbResults?search-url=/arenda/kvartiry/almaty/?das%5Bmap.complex%5D=1&isOnMap=0 (Caused by NewConnectionError('<urllib3.connection.HTTPSConnection object at 0x7fb0cb9b7e90>: Failed to establish a new connection: Error connecting to SOCKS5 proxy localhost:9150: [Errno 111] Connection refused'))
2024-02-10 17:06:09.860 | ERROR    | __main__:parse_data:87 - error
Traceback (most recent call last):

  File "/mnt/E83C5EC13C5E8A88/projects/etagi/.venv/lib/python3.11/site-packages/socks.py", line 787, in connect
    super(socksocket, self).connect(proxy_addr)
          │           │             └ 'localhost'
          │           └ <socks.socksocket [closed] fd=-1, family=2, type=1, proto=6>
          └ <class 'socks.socksocket'>

ConnectionRefusedError: [Errno 111] Connection refused


During handling of the above exception, another exception occurred:


Traceback (most recent call last):

  File "/mnt/E83C5EC13C5E8A88/projects/etagi/.venv/lib/python3.11/site-packages/urllib3/connection.py", line 198, in _new_conn
    sock = connection.create_connection(
           │          └ <function create_connection at 0x7fb0cdb854e0>
           └ <module 'urllib3.util.connection' from '/mnt/E83C5EC13C5E8A88/projects/etagi/.venv/lib/python3.11/site-packages/urllib3/util/...
  File "/mnt/E83C5EC13C5E8A88/projects/etagi/.venv/lib/python3.11/site-packages/urllib3/util/connection.py", line 85, in create_connection
    raise err
          └ None
  File "/mnt/E83C5EC13C5E8A88/projects/etagi/.venv/lib/python3.11/site-packages/urllib3/util/connection.py", line 73, in create_connection
    sock.connect(sa)
    │    │       └ ('185.143.129.90', 443)
    │    └ <function socksocket.connect at 0x7fb0ccfac860>
    └ <socks.socksocket [closed] fd=-1, family=2, type=1, proto=6>
  File "/mnt/E83C5EC13C5E8A88/projects/etagi/.venv/lib/python3.11/site-packages/socks.py", line 47, in wrapper
    return function(*args, **kwargs)
           │         │       └ {}
           │         └ (<socks.socksocket [closed] fd=-1, family=2, type=1, proto=6>, ('185.143.129.90', 443))
           └ <function socksocket.connect at 0x7fb0ccfac7c0>
  File "/mnt/E83C5EC13C5E8A88/projects/etagi/.venv/lib/python3.11/site-packages/socks.py", line 800, in connect
    raise ProxyConnectionError(msg, error)
          │                    └ 'Error connecting to SOCKS5 proxy localhost:9150'
          └ <class 'socks.ProxyConnectionError'>

socks.ProxyConnectionError: Error connecting to SOCKS5 proxy localhost:9150: [Errno 111] Connection refused


The above exception was the direct cause of the following exception:


Traceback (most recent call last):

  File "/mnt/E83C5EC13C5E8A88/projects/etagi/.venv/lib/python3.11/site-packages/urllib3/connectionpool.py", line 793, in urlopen
    response = self._make_request(
               │    └ <function HTTPConnectionPool._make_request at 0x7fb0cd3b8fe0>
               └ <urllib3.connectionpool.HTTPSConnectionPool object at 0x7fb0cb9e8490>
  File "/mnt/E83C5EC13C5E8A88/projects/etagi/.venv/lib/python3.11/site-packages/urllib3/connectionpool.py", line 491, in _make_request
    raise new_e
          └ NewConnectionError('<urllib3.connection.HTTPSConnection object at 0x7fb0cb9eb550>: Failed to establish a new connection: Erro...
  File "/mnt/E83C5EC13C5E8A88/projects/etagi/.venv/lib/python3.11/site-packages/urllib3/connectionpool.py", line 467, in _make_request
    self._validate_conn(conn)
    │    │              └ <urllib3.connection.HTTPSConnection object at 0x7fb0cb9eb550>
    │    └ <function HTTPSConnectionPool._validate_conn at 0x7fb0cd3b9580>
    └ <urllib3.connectionpool.HTTPSConnectionPool object at 0x7fb0cb9e8490>
  File "/mnt/E83C5EC13C5E8A88/projects/etagi/.venv/lib/python3.11/site-packages/urllib3/connectionpool.py", line 1099, in _validate_conn
    conn.connect()
    │    └ <function HTTPSConnection.connect at 0x7fb0cd3a1260>
    └ <urllib3.connection.HTTPSConnection object at 0x7fb0cb9eb550>
  File "/mnt/E83C5EC13C5E8A88/projects/etagi/.venv/lib/python3.11/site-packages/urllib3/connection.py", line 616, in connect
    self.sock = sock = self._new_conn()
    │    │             │    └ <function HTTPConnection._new_conn at 0x7fb0cd3a0900>
    │    │             └ <urllib3.connection.HTTPSConnection object at 0x7fb0cb9eb550>
    │    └ None
    └ <urllib3.connection.HTTPSConnection object at 0x7fb0cb9eb550>
  File "/mnt/E83C5EC13C5E8A88/projects/etagi/.venv/lib/python3.11/site-packages/urllib3/connection.py", line 213, in _new_conn
    raise NewConnectionError(
          └ <class 'urllib3.exceptions.NewConnectionError'>

urllib3.exceptions.NewConnectionError: <urllib3.connection.HTTPSConnection object at 0x7fb0cb9eb550>: Failed to establish a new connection: Error connecting to SOCKS5 proxy localhost:9150: [Errno 111] Connection refused


The above exception was the direct cause of the following exception:


Traceback (most recent call last):

  File "/mnt/E83C5EC13C5E8A88/projects/etagi/.venv/lib/python3.11/site-packages/requests/adapters.py", line 486, in send
    resp = conn.urlopen(
           │    └ <function HTTPConnectionPool.urlopen at 0x7fb0cd3b91c0>
           └ <urllib3.connectionpool.HTTPSConnectionPool object at 0x7fb0cb9e8490>
  File "/mnt/E83C5EC13C5E8A88/projects/etagi/.venv/lib/python3.11/site-packages/urllib3/connectionpool.py", line 847, in urlopen
    retries = retries.increment(
              │       └ <function Retry.increment at 0x7fb0cd318040>
              └ Retry(total=0, connect=None, read=False, redirect=None, status=None)
  File "/mnt/E83C5EC13C5E8A88/projects/etagi/.venv/lib/python3.11/site-packages/urllib3/util/retry.py", line 515, in increment
    raise MaxRetryError(_pool, url, reason) from reason  # type: ignore[arg-type]
          │             │      │    │            └ NewConnectionError('<urllib3.connection.HTTPSConnection object at 0x7fb0cb9eb550>: Failed to establish a new connection: Erro...
          │             │      │    └ NewConnectionError('<urllib3.connection.HTTPSConnection object at 0x7fb0cb9eb550>: Failed to establish a new connection: Erro...
          │             │      └ '/a/ajaxGetSearchNbResults?search-url=/arenda/kvartiry/almaty/?das%5Bmap.complex%5D=2&isOnMap=0'
          │             └ <urllib3.connectionpool.HTTPSConnectionPool object at 0x7fb0cb9e8490>
          └ <class 'urllib3.exceptions.MaxRetryError'>

urllib3.exceptions.MaxRetryError: HTTPSConnectionPool(host='krisha.kz', port=443): Max retries exceeded with url: /a/ajaxGetSearchNbResults?search-url=/arenda/kvartiry/almaty/?das%5Bmap.complex%5D=2&isOnMap=0 (Caused by NewConnectionError('<urllib3.connection.HTTPSConnection object at 0x7fb0cb9eb550>: Failed to establish a new connection: Error connecting to SOCKS5 proxy localhost:9150: [Errno 111] Connection refused'))


During handling of the above exception, another exception occurred:


Traceback (most recent call last):

  File "/mnt/E83C5EC13C5E8A88/projects/etagi/nb_parser.py", line 92, in <module>
    parse_data()
    └ <function parse_data at 0x7fb0cb979bc0>

> File "/mnt/E83C5EC13C5E8A88/projects/etagi/nb_parser.py", line 61, in parse_data
    r = requests.get(url=querry.format(str(i)), headers=headers)
        │        │       │      │          │            └ {'Host': 'krisha.kz', 'User-Agent': 'Mozilla/5.0 (X11; Ubuntu; Linux x86_64; rv:109.0) Gecko/20100101 Firefox/119.0', 'Accept...
        │        │       │      │          └ 2
        │        │       │      └ <method 'format' of 'str' objects>
        │        │       └ 'https://krisha.kz/a/ajaxGetSearchNbResults?search-url=/arenda/kvartiry/almaty/?das[map.complex]={}&isOnMap=0'
        │        └ <function get at 0x7fb0ccf42ac0>
        └ <module 'requests' from '/mnt/E83C5EC13C5E8A88/projects/etagi/.venv/lib/python3.11/site-packages/requests/__init__.py'>

  File "/mnt/E83C5EC13C5E8A88/projects/etagi/.venv/lib/python3.11/site-packages/requests/api.py", line 73, in get
    return request("get", url, params=params, **kwargs)
           │              │           │         └ {'headers': {'Host': 'krisha.kz', 'User-Agent': 'Mozilla/5.0 (X11; Ubuntu; Linux x86_64; rv:109.0) Gecko/20100101 Firefox/119...
           │              │           └ None
           │              └ 'https://krisha.kz/a/ajaxGetSearchNbResults?search-url=/arenda/kvartiry/almaty/?das[map.complex]=2&isOnMap=0'
           └ <function request at 0x7fb0ccf59bc0>
  File "/mnt/E83C5EC13C5E8A88/projects/etagi/.venv/lib/python3.11/site-packages/requests/api.py", line 59, in request
    return session.request(method=method, url=url, **kwargs)
           │       │              │           │      └ {'params': None, 'headers': {'Host': 'krisha.kz', 'User-Agent': 'Mozilla/5.0 (X11; Ubuntu; Linux x86_64; rv:109.0) Gecko/2010...
           │       │              │           └ 'https://krisha.kz/a/ajaxGetSearchNbResults?search-url=/arenda/kvartiry/almaty/?das[map.complex]=2&isOnMap=0'
           │       │              └ 'get'
           │       └ <function Session.request at 0x7fb0ccfadd00>
           └ <requests.sessions.Session object at 0x7fb0ccddb610>
  File "/mnt/E83C5EC13C5E8A88/projects/etagi/.venv/lib/python3.11/site-packages/requests/sessions.py", line 589, in request
    resp = self.send(prep, **send_kwargs)
           │    │    │       └ {'timeout': None, 'allow_redirects': True, 'proxies': OrderedDict(), 'stream': False, 'verify': True, 'cert': None}
           │    │    └ <PreparedRequest [GET]>
           │    └ <function Session.send at 0x7fb0ccfae200>
           └ <requests.sessions.Session object at 0x7fb0ccddb610>
  File "/mnt/E83C5EC13C5E8A88/projects/etagi/.venv/lib/python3.11/site-packages/requests/sessions.py", line 703, in send
    r = adapter.send(request, **kwargs)
        │       │    │          └ {'timeout': None, 'proxies': OrderedDict(), 'stream': False, 'verify': True, 'cert': None}
        │       │    └ <PreparedRequest [GET]>
        │       └ <function HTTPAdapter.send at 0x7fb0ccfad580>
        └ <requests.adapters.HTTPAdapter object at 0x7fb0cb9d7e50>
  File "/mnt/E83C5EC13C5E8A88/projects/etagi/.venv/lib/python3.11/site-packages/requests/adapters.py", line 519, in send
    raise ConnectionError(e, request=request)
          │                          └ <PreparedRequest [GET]>
          └ <class 'requests.exceptions.ConnectionError'>

requests.exceptions.ConnectionError: HTTPSConnectionPool(host='krisha.kz', port=443): Max retries exceeded with url: /a/ajaxGetSearchNbResults?search-url=/arenda/kvartiry/almaty/?das%5Bmap.complex%5D=2&isOnMap=0 (Caused by NewConnectionError('<urllib3.connection.HTTPSConnection object at 0x7fb0cb9eb550>: Failed to establish a new connection: Error connecting to SOCKS5 proxy localhost:9150: [Errno 111] Connection refused'))
2024-02-10 17:06:09.876 | ERROR    | __main__:parse_data:87 - error
Traceback (most recent call last):

  File "/mnt/E83C5EC13C5E8A88/projects/etagi/.venv/lib/python3.11/site-packages/socks.py", line 787, in connect
    super(socksocket, self).connect(proxy_addr)
          │           │             └ 'localhost'
          │           └ <socks.socksocket [closed] fd=-1, family=2, type=1, proto=6>
          └ <class 'socks.socksocket'>

ConnectionRefusedError: [Errno 111] Connection refused


During handling of the above exception, another exception occurred:


Traceback (most recent call last):

  File "/mnt/E83C5EC13C5E8A88/projects/etagi/.venv/lib/python3.11/site-packages/urllib3/connection.py", line 198, in _new_conn
    sock = connection.create_connection(
           │          └ <function create_connection at 0x7fb0cdb854e0>
           └ <module 'urllib3.util.connection' from '/mnt/E83C5EC13C5E8A88/projects/etagi/.venv/lib/python3.11/site-packages/urllib3/util/...
  File "/mnt/E83C5EC13C5E8A88/projects/etagi/.venv/lib/python3.11/site-packages/urllib3/util/connection.py", line 85, in create_connection
    raise err
          └ None
  File "/mnt/E83C5EC13C5E8A88/projects/etagi/.venv/lib/python3.11/site-packages/urllib3/util/connection.py", line 73, in create_connection
    sock.connect(sa)
    │    │       └ ('185.143.129.90', 443)
    │    └ <function socksocket.connect at 0x7fb0ccfac860>
    └ <socks.socksocket [closed] fd=-1, family=2, type=1, proto=6>
  File "/mnt/E83C5EC13C5E8A88/projects/etagi/.venv/lib/python3.11/site-packages/socks.py", line 47, in wrapper
    return function(*args, **kwargs)
           │         │       └ {}
           │         └ (<socks.socksocket [closed] fd=-1, family=2, type=1, proto=6>, ('185.143.129.90', 443))
           └ <function socksocket.connect at 0x7fb0ccfac7c0>
  File "/mnt/E83C5EC13C5E8A88/projects/etagi/.venv/lib/python3.11/site-packages/socks.py", line 800, in connect
    raise ProxyConnectionError(msg, error)
          │                    └ 'Error connecting to SOCKS5 proxy localhost:9150'
          └ <class 'socks.ProxyConnectionError'>

socks.ProxyConnectionError: Error connecting to SOCKS5 proxy localhost:9150: [Errno 111] Connection refused


The above exception was the direct cause of the following exception:


Traceback (most recent call last):

  File "/mnt/E83C5EC13C5E8A88/projects/etagi/.venv/lib/python3.11/site-packages/urllib3/connectionpool.py", line 793, in urlopen
    response = self._make_request(
               │    └ <function HTTPConnectionPool._make_request at 0x7fb0cd3b8fe0>
               └ <urllib3.connectionpool.HTTPSConnectionPool object at 0x7fb0cb9ed3d0>
  File "/mnt/E83C5EC13C5E8A88/projects/etagi/.venv/lib/python3.11/site-packages/urllib3/connectionpool.py", line 491, in _make_request
    raise new_e
          └ NewConnectionError('<urllib3.connection.HTTPSConnection object at 0x7fb0cb9ee3d0>: Failed to establish a new connection: Erro...
  File "/mnt/E83C5EC13C5E8A88/projects/etagi/.venv/lib/python3.11/site-packages/urllib3/connectionpool.py", line 467, in _make_request
    self._validate_conn(conn)
    │    │              └ <urllib3.connection.HTTPSConnection object at 0x7fb0cb9ee3d0>
    │    └ <function HTTPSConnectionPool._validate_conn at 0x7fb0cd3b9580>
    └ <urllib3.connectionpool.HTTPSConnectionPool object at 0x7fb0cb9ed3d0>
  File "/mnt/E83C5EC13C5E8A88/projects/etagi/.venv/lib/python3.11/site-packages/urllib3/connectionpool.py", line 1099, in _validate_conn
    conn.connect()
    │    └ <function HTTPSConnection.connect at 0x7fb0cd3a1260>
    └ <urllib3.connection.HTTPSConnection object at 0x7fb0cb9ee3d0>
  File "/mnt/E83C5EC13C5E8A88/projects/etagi/.venv/lib/python3.11/site-packages/urllib3/connection.py", line 616, in connect
    self.sock = sock = self._new_conn()
    │    │             │    └ <function HTTPConnection._new_conn at 0x7fb0cd3a0900>
    │    │             └ <urllib3.connection.HTTPSConnection object at 0x7fb0cb9ee3d0>
    │    └ None
    └ <urllib3.connection.HTTPSConnection object at 0x7fb0cb9ee3d0>
  File "/mnt/E83C5EC13C5E8A88/projects/etagi/.venv/lib/python3.11/site-packages/urllib3/connection.py", line 213, in _new_conn
    raise NewConnectionError(
          └ <class 'urllib3.exceptions.NewConnectionError'>

urllib3.exceptions.NewConnectionError: <urllib3.connection.HTTPSConnection object at 0x7fb0cb9ee3d0>: Failed to establish a new connection: Error connecting to SOCKS5 proxy localhost:9150: [Errno 111] Connection refused


The above exception was the direct cause of the following exception:


Traceback (most recent call last):

  File "/mnt/E83C5EC13C5E8A88/projects/etagi/.venv/lib/python3.11/site-packages/requests/adapters.py", line 486, in send
    resp = conn.urlopen(
           │    └ <function HTTPConnectionPool.urlopen at 0x7fb0cd3b91c0>
           └ <urllib3.connectionpool.HTTPSConnectionPool object at 0x7fb0cb9ed3d0>
  File "/mnt/E83C5EC13C5E8A88/projects/etagi/.venv/lib/python3.11/site-packages/urllib3/connectionpool.py", line 847, in urlopen
    retries = retries.increment(
              │       └ <function Retry.increment at 0x7fb0cd318040>
              └ Retry(total=0, connect=None, read=False, redirect=None, status=None)
  File "/mnt/E83C5EC13C5E8A88/projects/etagi/.venv/lib/python3.11/site-packages/urllib3/util/retry.py", line 515, in increment
    raise MaxRetryError(_pool, url, reason) from reason  # type: ignore[arg-type]
          │             │      │    │            └ NewConnectionError('<urllib3.connection.HTTPSConnection object at 0x7fb0cb9ee3d0>: Failed to establish a new connection: Erro...
          │             │      │    └ NewConnectionError('<urllib3.connection.HTTPSConnection object at 0x7fb0cb9ee3d0>: Failed to establish a new connection: Erro...
          │             │      └ '/a/ajaxGetSearchNbResults?search-url=/arenda/kvartiry/almaty/?das%5Bmap.complex%5D=3&isOnMap=0'
          │             └ <urllib3.connectionpool.HTTPSConnectionPool object at 0x7fb0cb9ed3d0>
          └ <class 'urllib3.exceptions.MaxRetryError'>

urllib3.exceptions.MaxRetryError: HTTPSConnectionPool(host='krisha.kz', port=443): Max retries exceeded with url: /a/ajaxGetSearchNbResults?search-url=/arenda/kvartiry/almaty/?das%5Bmap.complex%5D=3&isOnMap=0 (Caused by NewConnectionError('<urllib3.connection.HTTPSConnection object at 0x7fb0cb9ee3d0>: Failed to establish a new connection: Error connecting to SOCKS5 proxy localhost:9150: [Errno 111] Connection refused'))


During handling of the above exception, another exception occurred:


Traceback (most recent call last):

  File "/mnt/E83C5EC13C5E8A88/projects/etagi/nb_parser.py", line 92, in <module>
    parse_data()
    └ <function parse_data at 0x7fb0cb979bc0>

> File "/mnt/E83C5EC13C5E8A88/projects/etagi/nb_parser.py", line 61, in parse_data
    r = requests.get(url=querry.format(str(i)), headers=headers)
        │        │       │      │          │            └ {'Host': 'krisha.kz', 'User-Agent': 'Mozilla/5.0 (X11; Ubuntu; Linux x86_64; rv:109.0) Gecko/20100101 Firefox/119.0', 'Accept...
        │        │       │      │          └ 3
        │        │       │      └ <method 'format' of 'str' objects>
        │        │       └ 'https://krisha.kz/a/ajaxGetSearchNbResults?search-url=/arenda/kvartiry/almaty/?das[map.complex]={}&isOnMap=0'
        │        └ <function get at 0x7fb0ccf42ac0>
        └ <module 'requests' from '/mnt/E83C5EC13C5E8A88/projects/etagi/.venv/lib/python3.11/site-packages/requests/__init__.py'>

  File "/mnt/E83C5EC13C5E8A88/projects/etagi/.venv/lib/python3.11/site-packages/requests/api.py", line 73, in get
    return request("get", url, params=params, **kwargs)
           │              │           │         └ {'headers': {'Host': 'krisha.kz', 'User-Agent': 'Mozilla/5.0 (X11; Ubuntu; Linux x86_64; rv:109.0) Gecko/20100101 Firefox/119...
           │              │           └ None
           │              └ 'https://krisha.kz/a/ajaxGetSearchNbResults?search-url=/arenda/kvartiry/almaty/?das[map.complex]=3&isOnMap=0'
           └ <function request at 0x7fb0ccf59bc0>
  File "/mnt/E83C5EC13C5E8A88/projects/etagi/.venv/lib/python3.11/site-packages/requests/api.py", line 59, in request
    return session.request(method=method, url=url, **kwargs)
           │       │              │           │      └ {'params': None, 'headers': {'Host': 'krisha.kz', 'User-Agent': 'Mozilla/5.0 (X11; Ubuntu; Linux x86_64; rv:109.0) Gecko/2010...
           │       │              │           └ 'https://krisha.kz/a/ajaxGetSearchNbResults?search-url=/arenda/kvartiry/almaty/?das[map.complex]=3&isOnMap=0'
           │       │              └ 'get'
           │       └ <function Session.request at 0x7fb0ccfadd00>
           └ <requests.sessions.Session object at 0x7fb0cb9e34d0>
  File "/mnt/E83C5EC13C5E8A88/projects/etagi/.venv/lib/python3.11/site-packages/requests/sessions.py", line 589, in request
    resp = self.send(prep, **send_kwargs)
           │    │    │       └ {'timeout': None, 'allow_redirects': True, 'proxies': OrderedDict(), 'stream': False, 'verify': True, 'cert': None}
           │    │    └ <PreparedRequest [GET]>
           │    └ <function Session.send at 0x7fb0ccfae200>
           └ <requests.sessions.Session object at 0x7fb0cb9e34d0>
  File "/mnt/E83C5EC13C5E8A88/projects/etagi/.venv/lib/python3.11/site-packages/requests/sessions.py", line 703, in send
    r = adapter.send(request, **kwargs)
        │       │    │          └ {'timeout': None, 'proxies': OrderedDict(), 'stream': False, 'verify': True, 'cert': None}
        │       │    └ <PreparedRequest [GET]>
        │       └ <function HTTPAdapter.send at 0x7fb0ccfad580>
        └ <requests.adapters.HTTPAdapter object at 0x7fb0cb9beb50>
  File "/mnt/E83C5EC13C5E8A88/projects/etagi/.venv/lib/python3.11/site-packages/requests/adapters.py", line 519, in send
    raise ConnectionError(e, request=request)
          │                          └ <PreparedRequest [GET]>
          └ <class 'requests.exceptions.ConnectionError'>

requests.exceptions.ConnectionError: HTTPSConnectionPool(host='krisha.kz', port=443): Max retries exceeded with url: /a/ajaxGetSearchNbResults?search-url=/arenda/kvartiry/almaty/?das%5Bmap.complex%5D=3&isOnMap=0 (Caused by NewConnectionError('<urllib3.connection.HTTPSConnection object at 0x7fb0cb9ee3d0>: Failed to establish a new connection: Error connecting to SOCKS5 proxy localhost:9150: [Errno 111] Connection refused'))
2024-02-10 17:06:09.893 | ERROR    | __main__:parse_data:87 - error
Traceback (most recent call last):

  File "/mnt/E83C5EC13C5E8A88/projects/etagi/.venv/lib/python3.11/site-packages/socks.py", line 787, in connect
    super(socksocket, self).connect(proxy_addr)
          │           │             └ 'localhost'
          │           └ <socks.socksocket [closed] fd=-1, family=2, type=1, proto=6>
          └ <class 'socks.socksocket'>

ConnectionRefusedError: [Errno 111] Connection refused


During handling of the above exception, another exception occurred:


Traceback (most recent call last):

  File "/mnt/E83C5EC13C5E8A88/projects/etagi/.venv/lib/python3.11/site-packages/urllib3/connection.py", line 198, in _new_conn
    sock = connection.create_connection(
           │          └ <function create_connection at 0x7fb0cdb854e0>
           └ <module 'urllib3.util.connection' from '/mnt/E83C5EC13C5E8A88/projects/etagi/.venv/lib/python3.11/site-packages/urllib3/util/...
  File "/mnt/E83C5EC13C5E8A88/projects/etagi/.venv/lib/python3.11/site-packages/urllib3/util/connection.py", line 85, in create_connection
    raise err
          └ None
  File "/mnt/E83C5EC13C5E8A88/projects/etagi/.venv/lib/python3.11/site-packages/urllib3/util/connection.py", line 73, in create_connection
    sock.connect(sa)
    │    │       └ ('185.143.129.90', 443)
    │    └ <function socksocket.connect at 0x7fb0ccfac860>
    └ <socks.socksocket [closed] fd=-1, family=2, type=1, proto=6>
  File "/mnt/E83C5EC13C5E8A88/projects/etagi/.venv/lib/python3.11/site-packages/socks.py", line 47, in wrapper
    return function(*args, **kwargs)
           │         │       └ {}
           │         └ (<socks.socksocket [closed] fd=-1, family=2, type=1, proto=6>, ('185.143.129.90', 443))
           └ <function socksocket.connect at 0x7fb0ccfac7c0>
  File "/mnt/E83C5EC13C5E8A88/projects/etagi/.venv/lib/python3.11/site-packages/socks.py", line 800, in connect
    raise ProxyConnectionError(msg, error)
          │                    └ 'Error connecting to SOCKS5 proxy localhost:9150'
          └ <class 'socks.ProxyConnectionError'>

socks.ProxyConnectionError: Error connecting to SOCKS5 proxy localhost:9150: [Errno 111] Connection refused


The above exception was the direct cause of the following exception:


Traceback (most recent call last):

  File "/mnt/E83C5EC13C5E8A88/projects/etagi/.venv/lib/python3.11/site-packages/urllib3/connectionpool.py", line 793, in urlopen
    response = self._make_request(
               │    └ <function HTTPConnectionPool._make_request at 0x7fb0cd3b8fe0>
               └ <urllib3.connectionpool.HTTPSConnectionPool object at 0x7fb0cb8541d0>
  File "/mnt/E83C5EC13C5E8A88/projects/etagi/.venv/lib/python3.11/site-packages/urllib3/connectionpool.py", line 491, in _make_request
    raise new_e
          └ NewConnectionError('<urllib3.connection.HTTPSConnection object at 0x7fb0cb854f10>: Failed to establish a new connection: Erro...
  File "/mnt/E83C5EC13C5E8A88/projects/etagi/.venv/lib/python3.11/site-packages/urllib3/connectionpool.py", line 467, in _make_request
    self._validate_conn(conn)
    │    │              └ <urllib3.connection.HTTPSConnection object at 0x7fb0cb854f10>
    │    └ <function HTTPSConnectionPool._validate_conn at 0x7fb0cd3b9580>
    └ <urllib3.connectionpool.HTTPSConnectionPool object at 0x7fb0cb8541d0>
  File "/mnt/E83C5EC13C5E8A88/projects/etagi/.venv/lib/python3.11/site-packages/urllib3/connectionpool.py", line 1099, in _validate_conn
    conn.connect()
    │    └ <function HTTPSConnection.connect at 0x7fb0cd3a1260>
    └ <urllib3.connection.HTTPSConnection object at 0x7fb0cb854f10>
  File "/mnt/E83C5EC13C5E8A88/projects/etagi/.venv/lib/python3.11/site-packages/urllib3/connection.py", line 616, in connect
    self.sock = sock = self._new_conn()
    │    │             │    └ <function HTTPConnection._new_conn at 0x7fb0cd3a0900>
    │    │             └ <urllib3.connection.HTTPSConnection object at 0x7fb0cb854f10>
    │    └ None
    └ <urllib3.connection.HTTPSConnection object at 0x7fb0cb854f10>
  File "/mnt/E83C5EC13C5E8A88/projects/etagi/.venv/lib/python3.11/site-packages/urllib3/connection.py", line 213, in _new_conn
    raise NewConnectionError(
          └ <class 'urllib3.exceptions.NewConnectionError'>

urllib3.exceptions.NewConnectionError: <urllib3.connection.HTTPSConnection object at 0x7fb0cb854f10>: Failed to establish a new connection: Error connecting to SOCKS5 proxy localhost:9150: [Errno 111] Connection refused


The above exception was the direct cause of the following exception:


Traceback (most recent call last):

  File "/mnt/E83C5EC13C5E8A88/projects/etagi/.venv/lib/python3.11/site-packages/requests/adapters.py", line 486, in send
    resp = conn.urlopen(
           │    └ <function HTTPConnectionPool.urlopen at 0x7fb0cd3b91c0>
           └ <urllib3.connectionpool.HTTPSConnectionPool object at 0x7fb0cb8541d0>
  File "/mnt/E83C5EC13C5E8A88/projects/etagi/.venv/lib/python3.11/site-packages/urllib3/connectionpool.py", line 847, in urlopen
    retries = retries.increment(
              │       └ <function Retry.increment at 0x7fb0cd318040>
              └ Retry(total=0, connect=None, read=False, redirect=None, status=None)
  File "/mnt/E83C5EC13C5E8A88/projects/etagi/.venv/lib/python3.11/site-packages/urllib3/util/retry.py", line 515, in increment
    raise MaxRetryError(_pool, url, reason) from reason  # type: ignore[arg-type]
          │             │      │    │            └ NewConnectionError('<urllib3.connection.HTTPSConnection object at 0x7fb0cb854f10>: Failed to establish a new connection: Erro...
          │             │      │    └ NewConnectionError('<urllib3.connection.HTTPSConnection object at 0x7fb0cb854f10>: Failed to establish a new connection: Erro...
          │             │      └ '/a/ajaxGetSearchNbResults?search-url=/arenda/kvartiry/almaty/?das%5Bmap.complex%5D=4&isOnMap=0'
          │             └ <urllib3.connectionpool.HTTPSConnectionPool object at 0x7fb0cb8541d0>
          └ <class 'urllib3.exceptions.MaxRetryError'>

urllib3.exceptions.MaxRetryError: HTTPSConnectionPool(host='krisha.kz', port=443): Max retries exceeded with url: /a/ajaxGetSearchNbResults?search-url=/arenda/kvartiry/almaty/?das%5Bmap.complex%5D=4&isOnMap=0 (Caused by NewConnectionError('<urllib3.connection.HTTPSConnection object at 0x7fb0cb854f10>: Failed to establish a new connection: Error connecting to SOCKS5 proxy localhost:9150: [Errno 111] Connection refused'))


During handling of the above exception, another exception occurred:


Traceback (most recent call last):

  File "/mnt/E83C5EC13C5E8A88/projects/etagi/nb_parser.py", line 92, in <module>
    parse_data()
    └ <function parse_data at 0x7fb0cb979bc0>

> File "/mnt/E83C5EC13C5E8A88/projects/etagi/nb_parser.py", line 61, in parse_data
    r = requests.get(url=querry.format(str(i)), headers=headers)
        │        │       │      │          │            └ {'Host': 'krisha.kz', 'User-Agent': 'Mozilla/5.0 (X11; Ubuntu; Linux x86_64; rv:109.0) Gecko/20100101 Firefox/119.0', 'Accept...
        │        │       │      │          └ 4
        │        │       │      └ <method 'format' of 'str' objects>
        │        │       └ 'https://krisha.kz/a/ajaxGetSearchNbResults?search-url=/arenda/kvartiry/almaty/?das[map.complex]={}&isOnMap=0'
        │        └ <function get at 0x7fb0ccf42ac0>
        └ <module 'requests' from '/mnt/E83C5EC13C5E8A88/projects/etagi/.venv/lib/python3.11/site-packages/requests/__init__.py'>

  File "/mnt/E83C5EC13C5E8A88/projects/etagi/.venv/lib/python3.11/site-packages/requests/api.py", line 73, in get
    return request("get", url, params=params, **kwargs)
           │              │           │         └ {'headers': {'Host': 'krisha.kz', 'User-Agent': 'Mozilla/5.0 (X11; Ubuntu; Linux x86_64; rv:109.0) Gecko/20100101 Firefox/119...
           │              │           └ None
           │              └ 'https://krisha.kz/a/ajaxGetSearchNbResults?search-url=/arenda/kvartiry/almaty/?das[map.complex]=4&isOnMap=0'
           └ <function request at 0x7fb0ccf59bc0>
  File "/mnt/E83C5EC13C5E8A88/projects/etagi/.venv/lib/python3.11/site-packages/requests/api.py", line 59, in request
    return session.request(method=method, url=url, **kwargs)
           │       │              │           │      └ {'params': None, 'headers': {'Host': 'krisha.kz', 'User-Agent': 'Mozilla/5.0 (X11; Ubuntu; Linux x86_64; rv:109.0) Gecko/2010...
           │       │              │           └ 'https://krisha.kz/a/ajaxGetSearchNbResults?search-url=/arenda/kvartiry/almaty/?das[map.complex]=4&isOnMap=0'
           │       │              └ 'get'
           │       └ <function Session.request at 0x7fb0ccfadd00>
           └ <requests.sessions.Session object at 0x7fb0cb98ffd0>
  File "/mnt/E83C5EC13C5E8A88/projects/etagi/.venv/lib/python3.11/site-packages/requests/sessions.py", line 589, in request
    resp = self.send(prep, **send_kwargs)
           │    │    │       └ {'timeout': None, 'allow_redirects': True, 'proxies': OrderedDict(), 'stream': False, 'verify': True, 'cert': None}
           │    │    └ <PreparedRequest [GET]>
           │    └ <function Session.send at 0x7fb0ccfae200>
           └ <requests.sessions.Session object at 0x7fb0cb98ffd0>
  File "/mnt/E83C5EC13C5E8A88/projects/etagi/.venv/lib/python3.11/site-packages/requests/sessions.py", line 703, in send
    r = adapter.send(request, **kwargs)
        │       │    │          └ {'timeout': None, 'proxies': OrderedDict(), 'stream': False, 'verify': True, 'cert': None}
        │       │    └ <PreparedRequest [GET]>
        │       └ <function HTTPAdapter.send at 0x7fb0ccfad580>
        └ <requests.adapters.HTTPAdapter object at 0x7fb0cb9ed490>
  File "/mnt/E83C5EC13C5E8A88/projects/etagi/.venv/lib/python3.11/site-packages/requests/adapters.py", line 519, in send
    raise ConnectionError(e, request=request)
          │                          └ <PreparedRequest [GET]>
          └ <class 'requests.exceptions.ConnectionError'>

requests.exceptions.ConnectionError: HTTPSConnectionPool(host='krisha.kz', port=443): Max retries exceeded with url: /a/ajaxGetSearchNbResults?search-url=/arenda/kvartiry/almaty/?das%5Bmap.complex%5D=4&isOnMap=0 (Caused by NewConnectionError('<urllib3.connection.HTTPSConnection object at 0x7fb0cb854f10>: Failed to establish a new connection: Error connecting to SOCKS5 proxy localhost:9150: [Errno 111] Connection refused'))
2024-02-10 17:06:09.909 | ERROR    | __main__:parse_data:87 - error
Traceback (most recent call last):

  File "/mnt/E83C5EC13C5E8A88/projects/etagi/.venv/lib/python3.11/site-packages/socks.py", line 787, in connect
    super(socksocket, self).connect(proxy_addr)
          │           │             └ 'localhost'
          │           └ <socks.socksocket [closed] fd=-1, family=2, type=1, proto=6>
          └ <class 'socks.socksocket'>

ConnectionRefusedError: [Errno 111] Connection refused


During handling of the above exception, another exception occurred:


Traceback (most recent call last):

  File "/mnt/E83C5EC13C5E8A88/projects/etagi/.venv/lib/python3.11/site-packages/urllib3/connection.py", line 198, in _new_conn
    sock = connection.create_connection(
           │          └ <function create_connection at 0x7fb0cdb854e0>
           └ <module 'urllib3.util.connection' from '/mnt/E83C5EC13C5E8A88/projects/etagi/.venv/lib/python3.11/site-packages/urllib3/util/...
  File "/mnt/E83C5EC13C5E8A88/projects/etagi/.venv/lib/python3.11/site-packages/urllib3/util/connection.py", line 85, in create_connection
    raise err
          └ None
  File "/mnt/E83C5EC13C5E8A88/projects/etagi/.venv/lib/python3.11/site-packages/urllib3/util/connection.py", line 73, in create_connection
    sock.connect(sa)
    │    │       └ ('185.143.129.89', 443)
    │    └ <function socksocket.connect at 0x7fb0ccfac860>
    └ <socks.socksocket [closed] fd=-1, family=2, type=1, proto=6>
  File "/mnt/E83C5EC13C5E8A88/projects/etagi/.venv/lib/python3.11/site-packages/socks.py", line 47, in wrapper
    return function(*args, **kwargs)
           │         │       └ {}
           │         └ (<socks.socksocket [closed] fd=-1, family=2, type=1, proto=6>, ('185.143.129.89', 443))
           └ <function socksocket.connect at 0x7fb0ccfac7c0>
  File "/mnt/E83C5EC13C5E8A88/projects/etagi/.venv/lib/python3.11/site-packages/socks.py", line 800, in connect
    raise ProxyConnectionError(msg, error)
          │                    └ 'Error connecting to SOCKS5 proxy localhost:9150'
          └ <class 'socks.ProxyConnectionError'>

socks.ProxyConnectionError: Error connecting to SOCKS5 proxy localhost:9150: [Errno 111] Connection refused


The above exception was the direct cause of the following exception:


Traceback (most recent call last):

  File "/mnt/E83C5EC13C5E8A88/projects/etagi/.venv/lib/python3.11/site-packages/urllib3/connectionpool.py", line 793, in urlopen
    response = self._make_request(
               │    └ <function HTTPConnectionPool._make_request at 0x7fb0cd3b8fe0>
               └ <urllib3.connectionpool.HTTPSConnectionPool object at 0x7fb0cb856a90>
  File "/mnt/E83C5EC13C5E8A88/projects/etagi/.venv/lib/python3.11/site-packages/urllib3/connectionpool.py", line 491, in _make_request
    raise new_e
          └ NewConnectionError('<urllib3.connection.HTTPSConnection object at 0x7fb0cb857a90>: Failed to establish a new connection: Erro...
  File "/mnt/E83C5EC13C5E8A88/projects/etagi/.venv/lib/python3.11/site-packages/urllib3/connectionpool.py", line 467, in _make_request
    self._validate_conn(conn)
    │    │              └ <urllib3.connection.HTTPSConnection object at 0x7fb0cb857a90>
    │    └ <function HTTPSConnectionPool._validate_conn at 0x7fb0cd3b9580>
    └ <urllib3.connectionpool.HTTPSConnectionPool object at 0x7fb0cb856a90>
  File "/mnt/E83C5EC13C5E8A88/projects/etagi/.venv/lib/python3.11/site-packages/urllib3/connectionpool.py", line 1099, in _validate_conn
    conn.connect()
    │    └ <function HTTPSConnection.connect at 0x7fb0cd3a1260>
    └ <urllib3.connection.HTTPSConnection object at 0x7fb0cb857a90>
  File "/mnt/E83C5EC13C5E8A88/projects/etagi/.venv/lib/python3.11/site-packages/urllib3/connection.py", line 616, in connect
    self.sock = sock = self._new_conn()
    │    │             │    └ <function HTTPConnection._new_conn at 0x7fb0cd3a0900>
    │    │             └ <urllib3.connection.HTTPSConnection object at 0x7fb0cb857a90>
    │    └ None
    └ <urllib3.connection.HTTPSConnection object at 0x7fb0cb857a90>
  File "/mnt/E83C5EC13C5E8A88/projects/etagi/.venv/lib/python3.11/site-packages/urllib3/connection.py", line 213, in _new_conn
    raise NewConnectionError(
          └ <class 'urllib3.exceptions.NewConnectionError'>

urllib3.exceptions.NewConnectionError: <urllib3.connection.HTTPSConnection object at 0x7fb0cb857a90>: Failed to establish a new connection: Error connecting to SOCKS5 proxy localhost:9150: [Errno 111] Connection refused


The above exception was the direct cause of the following exception:


Traceback (most recent call last):

  File "/mnt/E83C5EC13C5E8A88/projects/etagi/.venv/lib/python3.11/site-packages/requests/adapters.py", line 486, in send
    resp = conn.urlopen(
           │    └ <function HTTPConnectionPool.urlopen at 0x7fb0cd3b91c0>
           └ <urllib3.connectionpool.HTTPSConnectionPool object at 0x7fb0cb856a90>
  File "/mnt/E83C5EC13C5E8A88/projects/etagi/.venv/lib/python3.11/site-packages/urllib3/connectionpool.py", line 847, in urlopen
    retries = retries.increment(
              │       └ <function Retry.increment at 0x7fb0cd318040>
              └ Retry(total=0, connect=None, read=False, redirect=None, status=None)
  File "/mnt/E83C5EC13C5E8A88/projects/etagi/.venv/lib/python3.11/site-packages/urllib3/util/retry.py", line 515, in increment
    raise MaxRetryError(_pool, url, reason) from reason  # type: ignore[arg-type]
          │             │      │    │            └ NewConnectionError('<urllib3.connection.HTTPSConnection object at 0x7fb0cb857a90>: Failed to establish a new connection: Erro...
          │             │      │    └ NewConnectionError('<urllib3.connection.HTTPSConnection object at 0x7fb0cb857a90>: Failed to establish a new connection: Erro...
          │             │      └ '/a/ajaxGetSearchNbResults?search-url=/arenda/kvartiry/almaty/?das%5Bmap.complex%5D=5&isOnMap=0'
          │             └ <urllib3.connectionpool.HTTPSConnectionPool object at 0x7fb0cb856a90>
          └ <class 'urllib3.exceptions.MaxRetryError'>

urllib3.exceptions.MaxRetryError: HTTPSConnectionPool(host='krisha.kz', port=443): Max retries exceeded with url: /a/ajaxGetSearchNbResults?search-url=/arenda/kvartiry/almaty/?das%5Bmap.complex%5D=5&isOnMap=0 (Caused by NewConnectionError('<urllib3.connection.HTTPSConnection object at 0x7fb0cb857a90>: Failed to establish a new connection: Error connecting to SOCKS5 proxy localhost:9150: [Errno 111] Connection refused'))


During handling of the above exception, another exception occurred:


Traceback (most recent call last):

  File "/mnt/E83C5EC13C5E8A88/projects/etagi/nb_parser.py", line 92, in <module>
    parse_data()
    └ <function parse_data at 0x7fb0cb979bc0>

> File "/mnt/E83C5EC13C5E8A88/projects/etagi/nb_parser.py", line 61, in parse_data
    r = requests.get(url=querry.format(str(i)), headers=headers)
        │        │       │      │          │            └ {'Host': 'krisha.kz', 'User-Agent': 'Mozilla/5.0 (X11; Ubuntu; Linux x86_64; rv:109.0) Gecko/20100101 Firefox/119.0', 'Accept...
        │        │       │      │          └ 5
        │        │       │      └ <method 'format' of 'str' objects>
        │        │       └ 'https://krisha.kz/a/ajaxGetSearchNbResults?search-url=/arenda/kvartiry/almaty/?das[map.complex]={}&isOnMap=0'
        │        └ <function get at 0x7fb0ccf42ac0>
        └ <module 'requests' from '/mnt/E83C5EC13C5E8A88/projects/etagi/.venv/lib/python3.11/site-packages/requests/__init__.py'>

  File "/mnt/E83C5EC13C5E8A88/projects/etagi/.venv/lib/python3.11/site-packages/requests/api.py", line 73, in get
    return request("get", url, params=params, **kwargs)
           │              │           │         └ {'headers': {'Host': 'krisha.kz', 'User-Agent': 'Mozilla/5.0 (X11; Ubuntu; Linux x86_64; rv:109.0) Gecko/20100101 Firefox/119...
           │              │           └ None
           │              └ 'https://krisha.kz/a/ajaxGetSearchNbResults?search-url=/arenda/kvartiry/almaty/?das[map.complex]=5&isOnMap=0'
           └ <function request at 0x7fb0ccf59bc0>
  File "/mnt/E83C5EC13C5E8A88/projects/etagi/.venv/lib/python3.11/site-packages/requests/api.py", line 59, in request
    return session.request(method=method, url=url, **kwargs)
           │       │              │           │      └ {'params': None, 'headers': {'Host': 'krisha.kz', 'User-Agent': 'Mozilla/5.0 (X11; Ubuntu; Linux x86_64; rv:109.0) Gecko/2010...
           │       │              │           └ 'https://krisha.kz/a/ajaxGetSearchNbResults?search-url=/arenda/kvartiry/almaty/?das[map.complex]=5&isOnMap=0'
           │       │              └ 'get'
           │       └ <function Session.request at 0x7fb0ccfadd00>
           └ <requests.sessions.Session object at 0x7fb0cb9ef290>
  File "/mnt/E83C5EC13C5E8A88/projects/etagi/.venv/lib/python3.11/site-packages/requests/sessions.py", line 589, in request
    resp = self.send(prep, **send_kwargs)
           │    │    │       └ {'timeout': None, 'allow_redirects': True, 'proxies': OrderedDict(), 'stream': False, 'verify': True, 'cert': None}
           │    │    └ <PreparedRequest [GET]>
           │    └ <function Session.send at 0x7fb0ccfae200>
           └ <requests.sessions.Session object at 0x7fb0cb9ef290>
  File "/mnt/E83C5EC13C5E8A88/projects/etagi/.venv/lib/python3.11/site-packages/requests/sessions.py", line 703, in send
    r = adapter.send(request, **kwargs)
        │       │    │          └ {'timeout': None, 'proxies': OrderedDict(), 'stream': False, 'verify': True, 'cert': None}
        │       │    └ <PreparedRequest [GET]>
        │       └ <function HTTPAdapter.send at 0x7fb0ccfad580>
        └ <requests.adapters.HTTPAdapter object at 0x7fb0cb8543d0>
  File "/mnt/E83C5EC13C5E8A88/projects/etagi/.venv/lib/python3.11/site-packages/requests/adapters.py", line 519, in send
    raise ConnectionError(e, request=request)
          │                          └ <PreparedRequest [GET]>
          └ <class 'requests.exceptions.ConnectionError'>

requests.exceptions.ConnectionError: HTTPSConnectionPool(host='krisha.kz', port=443): Max retries exceeded with url: /a/ajaxGetSearchNbResults?search-url=/arenda/kvartiry/almaty/?das%5Bmap.complex%5D=5&isOnMap=0 (Caused by NewConnectionError('<urllib3.connection.HTTPSConnection object at 0x7fb0cb857a90>: Failed to establish a new connection: Error connecting to SOCKS5 proxy localhost:9150: [Errno 111] Connection refused'))
2024-02-10 17:06:09.982 | ERROR    | __main__:parse_data:87 - error
Traceback (most recent call last):

  File "/mnt/E83C5EC13C5E8A88/projects/etagi/.venv/lib/python3.11/site-packages/socks.py", line 787, in connect
    super(socksocket, self).connect(proxy_addr)
          │           │             └ 'localhost'
          │           └ <socks.socksocket [closed] fd=-1, family=2, type=1, proto=6>
          └ <class 'socks.socksocket'>

ConnectionRefusedError: [Errno 111] Connection refused


During handling of the above exception, another exception occurred:


Traceback (most recent call last):

  File "/mnt/E83C5EC13C5E8A88/projects/etagi/.venv/lib/python3.11/site-packages/urllib3/connection.py", line 198, in _new_conn
    sock = connection.create_connection(
           │          └ <function create_connection at 0x7fb0cdb854e0>
           └ <module 'urllib3.util.connection' from '/mnt/E83C5EC13C5E8A88/projects/etagi/.venv/lib/python3.11/site-packages/urllib3/util/...
  File "/mnt/E83C5EC13C5E8A88/projects/etagi/.venv/lib/python3.11/site-packages/urllib3/util/connection.py", line 85, in create_connection
    raise err
          └ None
  File "/mnt/E83C5EC13C5E8A88/projects/etagi/.venv/lib/python3.11/site-packages/urllib3/util/connection.py", line 73, in create_connection
    sock.connect(sa)
    │    │       └ ('185.143.129.89', 443)
    │    └ <function socksocket.connect at 0x7fb0ccfac860>
    └ <socks.socksocket [closed] fd=-1, family=2, type=1, proto=6>
  File "/mnt/E83C5EC13C5E8A88/projects/etagi/.venv/lib/python3.11/site-packages/socks.py", line 47, in wrapper
    return function(*args, **kwargs)
           │         │       └ {}
           │         └ (<socks.socksocket [closed] fd=-1, family=2, type=1, proto=6>, ('185.143.129.89', 443))
           └ <function socksocket.connect at 0x7fb0ccfac7c0>
  File "/mnt/E83C5EC13C5E8A88/projects/etagi/.venv/lib/python3.11/site-packages/socks.py", line 800, in connect
    raise ProxyConnectionError(msg, error)
          │                    └ 'Error connecting to SOCKS5 proxy localhost:9150'
          └ <class 'socks.ProxyConnectionError'>

socks.ProxyConnectionError: Error connecting to SOCKS5 proxy localhost:9150: [Errno 111] Connection refused


The above exception was the direct cause of the following exception:


Traceback (most recent call last):

  File "/mnt/E83C5EC13C5E8A88/projects/etagi/.venv/lib/python3.11/site-packages/urllib3/connectionpool.py", line 793, in urlopen
    response = self._make_request(
               │    └ <function HTTPConnectionPool._make_request at 0x7fb0cd3b8fe0>
               └ <urllib3.connectionpool.HTTPSConnectionPool object at 0x7fb0cb8615d0>
  File "/mnt/E83C5EC13C5E8A88/projects/etagi/.venv/lib/python3.11/site-packages/urllib3/connectionpool.py", line 491, in _make_request
    raise new_e
          └ NewConnectionError('<urllib3.connection.HTTPSConnection object at 0x7fb0cb862610>: Failed to establish a new connection: Erro...
  File "/mnt/E83C5EC13C5E8A88/projects/etagi/.venv/lib/python3.11/site-packages/urllib3/connectionpool.py", line 467, in _make_request
    self._validate_conn(conn)
    │    │              └ <urllib3.connection.HTTPSConnection object at 0x7fb0cb862610>
    │    └ <function HTTPSConnectionPool._validate_conn at 0x7fb0cd3b9580>
    └ <urllib3.connectionpool.HTTPSConnectionPool object at 0x7fb0cb8615d0>
  File "/mnt/E83C5EC13C5E8A88/projects/etagi/.venv/lib/python3.11/site-packages/urllib3/connectionpool.py", line 1099, in _validate_conn
    conn.connect()
    │    └ <function HTTPSConnection.connect at 0x7fb0cd3a1260>
    └ <urllib3.connection.HTTPSConnection object at 0x7fb0cb862610>
  File "/mnt/E83C5EC13C5E8A88/projects/etagi/.venv/lib/python3.11/site-packages/urllib3/connection.py", line 616, in connect
    self.sock = sock = self._new_conn()
    │    │             │    └ <function HTTPConnection._new_conn at 0x7fb0cd3a0900>
    │    │             └ <urllib3.connection.HTTPSConnection object at 0x7fb0cb862610>
    │    └ None
    └ <urllib3.connection.HTTPSConnection object at 0x7fb0cb862610>
  File "/mnt/E83C5EC13C5E8A88/projects/etagi/.venv/lib/python3.11/site-packages/urllib3/connection.py", line 213, in _new_conn
    raise NewConnectionError(
          └ <class 'urllib3.exceptions.NewConnectionError'>

urllib3.exceptions.NewConnectionError: <urllib3.connection.HTTPSConnection object at 0x7fb0cb862610>: Failed to establish a new connection: Error connecting to SOCKS5 proxy localhost:9150: [Errno 111] Connection refused


The above exception was the direct cause of the following exception:


Traceback (most recent call last):

  File "/mnt/E83C5EC13C5E8A88/projects/etagi/.venv/lib/python3.11/site-packages/requests/adapters.py", line 486, in send
    resp = conn.urlopen(
           │    └ <function HTTPConnectionPool.urlopen at 0x7fb0cd3b91c0>
           └ <urllib3.connectionpool.HTTPSConnectionPool object at 0x7fb0cb8615d0>
  File "/mnt/E83C5EC13C5E8A88/projects/etagi/.venv/lib/python3.11/site-packages/urllib3/connectionpool.py", line 847, in urlopen
    retries = retries.increment(
              │       └ <function Retry.increment at 0x7fb0cd318040>
              └ Retry(total=0, connect=None, read=False, redirect=None, status=None)
  File "/mnt/E83C5EC13C5E8A88/projects/etagi/.venv/lib/python3.11/site-packages/urllib3/util/retry.py", line 515, in increment
    raise MaxRetryError(_pool, url, reason) from reason  # type: ignore[arg-type]
          │             │      │    │            └ NewConnectionError('<urllib3.connection.HTTPSConnection object at 0x7fb0cb862610>: Failed to establish a new connection: Erro...
          │             │      │    └ NewConnectionError('<urllib3.connection.HTTPSConnection object at 0x7fb0cb862610>: Failed to establish a new connection: Erro...
          │             │      └ '/a/ajaxGetSearchNbResults?search-url=/arenda/kvartiry/almaty/?das%5Bmap.complex%5D=6&isOnMap=0'
          │             └ <urllib3.connectionpool.HTTPSConnectionPool object at 0x7fb0cb8615d0>
          └ <class 'urllib3.exceptions.MaxRetryError'>

urllib3.exceptions.MaxRetryError: HTTPSConnectionPool(host='krisha.kz', port=443): Max retries exceeded with url: /a/ajaxGetSearchNbResults?search-url=/arenda/kvartiry/almaty/?das%5Bmap.complex%5D=6&isOnMap=0 (Caused by NewConnectionError('<urllib3.connection.HTTPSConnection object at 0x7fb0cb862610>: Failed to establish a new connection: Error connecting to SOCKS5 proxy localhost:9150: [Errno 111] Connection refused'))


During handling of the above exception, another exception occurred:


Traceback (most recent call last):

  File "/mnt/E83C5EC13C5E8A88/projects/etagi/nb_parser.py", line 92, in <module>
    parse_data()
    └ <function parse_data at 0x7fb0cb979bc0>

> File "/mnt/E83C5EC13C5E8A88/projects/etagi/nb_parser.py", line 61, in parse_data
    r = requests.get(url=querry.format(str(i)), headers=headers)
        │        │       │      │          │            └ {'Host': 'krisha.kz', 'User-Agent': 'Mozilla/5.0 (X11; Ubuntu; Linux x86_64; rv:109.0) Gecko/20100101 Firefox/119.0', 'Accept...
        │        │       │      │          └ 6
        │        │       │      └ <method 'format' of 'str' objects>
        │        │       └ 'https://krisha.kz/a/ajaxGetSearchNbResults?search-url=/arenda/kvartiry/almaty/?das[map.complex]={}&isOnMap=0'
        │        └ <function get at 0x7fb0ccf42ac0>
        └ <module 'requests' from '/mnt/E83C5EC13C5E8A88/projects/etagi/.venv/lib/python3.11/site-packages/requests/__init__.py'>

  File "/mnt/E83C5EC13C5E8A88/projects/etagi/.venv/lib/python3.11/site-packages/requests/api.py", line 73, in get
    return request("get", url, params=params, **kwargs)
           │              │           │         └ {'headers': {'Host': 'krisha.kz', 'User-Agent': 'Mozilla/5.0 (X11; Ubuntu; Linux x86_64; rv:109.0) Gecko/20100101 Firefox/119...
           │              │           └ None
           │              └ 'https://krisha.kz/a/ajaxGetSearchNbResults?search-url=/arenda/kvartiry/almaty/?das[map.complex]=6&isOnMap=0'
           └ <function request at 0x7fb0ccf59bc0>
  File "/mnt/E83C5EC13C5E8A88/projects/etagi/.venv/lib/python3.11/site-packages/requests/api.py", line 59, in request
    return session.request(method=method, url=url, **kwargs)
           │       │              │           │      └ {'params': None, 'headers': {'Host': 'krisha.kz', 'User-Agent': 'Mozilla/5.0 (X11; Ubuntu; Linux x86_64; rv:109.0) Gecko/2010...
           │       │              │           └ 'https://krisha.kz/a/ajaxGetSearchNbResults?search-url=/arenda/kvartiry/almaty/?das[map.complex]=6&isOnMap=0'
           │       │              └ 'get'
           │       └ <function Session.request at 0x7fb0ccfadd00>
           └ <requests.sessions.Session object at 0x7fb0ccddb490>
  File "/mnt/E83C5EC13C5E8A88/projects/etagi/.venv/lib/python3.11/site-packages/requests/sessions.py", line 589, in request
    resp = self.send(prep, **send_kwargs)
           │    │    │       └ {'timeout': None, 'allow_redirects': True, 'proxies': OrderedDict(), 'stream': False, 'verify': True, 'cert': None}
           │    │    └ <PreparedRequest [GET]>
           │    └ <function Session.send at 0x7fb0ccfae200>
           └ <requests.sessions.Session object at 0x7fb0ccddb490>
  File "/mnt/E83C5EC13C5E8A88/projects/etagi/.venv/lib/python3.11/site-packages/requests/sessions.py", line 703, in send
    r = adapter.send(request, **kwargs)
        │       │    │          └ {'timeout': None, 'proxies': OrderedDict(), 'stream': False, 'verify': True, 'cert': None}
        │       │    └ <PreparedRequest [GET]>
        │       └ <function HTTPAdapter.send at 0x7fb0ccfad580>
        └ <requests.adapters.HTTPAdapter object at 0x7fb0cb860210>
  File "/mnt/E83C5EC13C5E8A88/projects/etagi/.venv/lib/python3.11/site-packages/requests/adapters.py", line 519, in send
    raise ConnectionError(e, request=request)
          │                          └ <PreparedRequest [GET]>
          └ <class 'requests.exceptions.ConnectionError'>

requests.exceptions.ConnectionError: HTTPSConnectionPool(host='krisha.kz', port=443): Max retries exceeded with url: /a/ajaxGetSearchNbResults?search-url=/arenda/kvartiry/almaty/?das%5Bmap.complex%5D=6&isOnMap=0 (Caused by NewConnectionError('<urllib3.connection.HTTPSConnection object at 0x7fb0cb862610>: Failed to establish a new connection: Error connecting to SOCKS5 proxy localhost:9150: [Errno 111] Connection refused'))
2024-02-10 17:06:10.076 | ERROR    | __main__:parse_data:87 - error
Traceback (most recent call last):

  File "/mnt/E83C5EC13C5E8A88/projects/etagi/.venv/lib/python3.11/site-packages/socks.py", line 787, in connect
    super(socksocket, self).connect(proxy_addr)
          │           │             └ 'localhost'
          │           └ <socks.socksocket [closed] fd=-1, family=2, type=1, proto=6>
          └ <class 'socks.socksocket'>

ConnectionRefusedError: [Errno 111] Connection refused


During handling of the above exception, another exception occurred:


Traceback (most recent call last):

  File "/mnt/E83C5EC13C5E8A88/projects/etagi/.venv/lib/python3.11/site-packages/urllib3/connection.py", line 198, in _new_conn
    sock = connection.create_connection(
           │          └ <function create_connection at 0x7fb0cdb854e0>
           └ <module 'urllib3.util.connection' from '/mnt/E83C5EC13C5E8A88/projects/etagi/.venv/lib/python3.11/site-packages/urllib3/util/...
  File "/mnt/E83C5EC13C5E8A88/projects/etagi/.venv/lib/python3.11/site-packages/urllib3/util/connection.py", line 85, in create_connection
    raise err
          └ None
  File "/mnt/E83C5EC13C5E8A88/projects/etagi/.venv/lib/python3.11/site-packages/urllib3/util/connection.py", line 73, in create_connection
    sock.connect(sa)
    │    │       └ ('185.143.129.89', 443)
    │    └ <function socksocket.connect at 0x7fb0ccfac860>
    └ <socks.socksocket [closed] fd=-1, family=2, type=1, proto=6>
  File "/mnt/E83C5EC13C5E8A88/projects/etagi/.venv/lib/python3.11/site-packages/socks.py", line 47, in wrapper
    return function(*args, **kwargs)
           │         │       └ {}
           │         └ (<socks.socksocket [closed] fd=-1, family=2, type=1, proto=6>, ('185.143.129.89', 443))
           └ <function socksocket.connect at 0x7fb0ccfac7c0>
  File "/mnt/E83C5EC13C5E8A88/projects/etagi/.venv/lib/python3.11/site-packages/socks.py", line 800, in connect
    raise ProxyConnectionError(msg, error)
          │                    └ 'Error connecting to SOCKS5 proxy localhost:9150'
          └ <class 'socks.ProxyConnectionError'>

socks.ProxyConnectionError: Error connecting to SOCKS5 proxy localhost:9150: [Errno 111] Connection refused


The above exception was the direct cause of the following exception:


Traceback (most recent call last):

  File "/mnt/E83C5EC13C5E8A88/projects/etagi/.venv/lib/python3.11/site-packages/urllib3/connectionpool.py", line 793, in urlopen
    response = self._make_request(
               │    └ <function HTTPConnectionPool._make_request at 0x7fb0cd3b8fe0>
               └ <urllib3.connectionpool.HTTPSConnectionPool object at 0x7fb0cb857510>
  File "/mnt/E83C5EC13C5E8A88/projects/etagi/.venv/lib/python3.11/site-packages/urllib3/connectionpool.py", line 491, in _make_request
    raise new_e
          └ NewConnectionError('<urllib3.connection.HTTPSConnection object at 0x7fb0cb854250>: Failed to establish a new connection: Erro...
  File "/mnt/E83C5EC13C5E8A88/projects/etagi/.venv/lib/python3.11/site-packages/urllib3/connectionpool.py", line 467, in _make_request
    self._validate_conn(conn)
    │    │              └ <urllib3.connection.HTTPSConnection object at 0x7fb0cb854250>
    │    └ <function HTTPSConnectionPool._validate_conn at 0x7fb0cd3b9580>
    └ <urllib3.connectionpool.HTTPSConnectionPool object at 0x7fb0cb857510>
  File "/mnt/E83C5EC13C5E8A88/projects/etagi/.venv/lib/python3.11/site-packages/urllib3/connectionpool.py", line 1099, in _validate_conn
    conn.connect()
    │    └ <function HTTPSConnection.connect at 0x7fb0cd3a1260>
    └ <urllib3.connection.HTTPSConnection object at 0x7fb0cb854250>
  File "/mnt/E83C5EC13C5E8A88/projects/etagi/.venv/lib/python3.11/site-packages/urllib3/connection.py", line 616, in connect
    self.sock = sock = self._new_conn()
    │    │             │    └ <function HTTPConnection._new_conn at 0x7fb0cd3a0900>
    │    │             └ <urllib3.connection.HTTPSConnection object at 0x7fb0cb854250>
    │    └ None
    └ <urllib3.connection.HTTPSConnection object at 0x7fb0cb854250>
  File "/mnt/E83C5EC13C5E8A88/projects/etagi/.venv/lib/python3.11/site-packages/urllib3/connection.py", line 213, in _new_conn
    raise NewConnectionError(
          └ <class 'urllib3.exceptions.NewConnectionError'>

urllib3.exceptions.NewConnectionError: <urllib3.connection.HTTPSConnection object at 0x7fb0cb854250>: Failed to establish a new connection: Error connecting to SOCKS5 proxy localhost:9150: [Errno 111] Connection refused


The above exception was the direct cause of the following exception:


Traceback (most recent call last):

  File "/mnt/E83C5EC13C5E8A88/projects/etagi/.venv/lib/python3.11/site-packages/requests/adapters.py", line 486, in send
    resp = conn.urlopen(
           │    └ <function HTTPConnectionPool.urlopen at 0x7fb0cd3b91c0>
           └ <urllib3.connectionpool.HTTPSConnectionPool object at 0x7fb0cb857510>
  File "/mnt/E83C5EC13C5E8A88/projects/etagi/.venv/lib/python3.11/site-packages/urllib3/connectionpool.py", line 847, in urlopen
    retries = retries.increment(
              │       └ <function Retry.increment at 0x7fb0cd318040>
              └ Retry(total=0, connect=None, read=False, redirect=None, status=None)
  File "/mnt/E83C5EC13C5E8A88/projects/etagi/.venv/lib/python3.11/site-packages/urllib3/util/retry.py", line 515, in increment
    raise MaxRetryError(_pool, url, reason) from reason  # type: ignore[arg-type]
          │             │      │    │            └ NewConnectionError('<urllib3.connection.HTTPSConnection object at 0x7fb0cb854250>: Failed to establish a new connection: Erro...
          │             │      │    └ NewConnectionError('<urllib3.connection.HTTPSConnection object at 0x7fb0cb854250>: Failed to establish a new connection: Erro...
          │             │      └ '/a/ajaxGetSearchNbResults?search-url=/arenda/kvartiry/almaty/?das%5Bmap.complex%5D=7&isOnMap=0'
          │             └ <urllib3.connectionpool.HTTPSConnectionPool object at 0x7fb0cb857510>
          └ <class 'urllib3.exceptions.MaxRetryError'>

urllib3.exceptions.MaxRetryError: HTTPSConnectionPool(host='krisha.kz', port=443): Max retries exceeded with url: /a/ajaxGetSearchNbResults?search-url=/arenda/kvartiry/almaty/?das%5Bmap.complex%5D=7&isOnMap=0 (Caused by NewConnectionError('<urllib3.connection.HTTPSConnection object at 0x7fb0cb854250>: Failed to establish a new connection: Error connecting to SOCKS5 proxy localhost:9150: [Errno 111] Connection refused'))


During handling of the above exception, another exception occurred:


Traceback (most recent call last):

  File "/mnt/E83C5EC13C5E8A88/projects/etagi/nb_parser.py", line 92, in <module>
    parse_data()
    └ <function parse_data at 0x7fb0cb979bc0>

> File "/mnt/E83C5EC13C5E8A88/projects/etagi/nb_parser.py", line 61, in parse_data
    r = requests.get(url=querry.format(str(i)), headers=headers)
        │        │       │      │          │            └ {'Host': 'krisha.kz', 'User-Agent': 'Mozilla/5.0 (X11; Ubuntu; Linux x86_64; rv:109.0) Gecko/20100101 Firefox/119.0', 'Accept...
        │        │       │      │          └ 7
        │        │       │      └ <method 'format' of 'str' objects>
        │        │       └ 'https://krisha.kz/a/ajaxGetSearchNbResults?search-url=/arenda/kvartiry/almaty/?das[map.complex]={}&isOnMap=0'
        │        └ <function get at 0x7fb0ccf42ac0>
        └ <module 'requests' from '/mnt/E83C5EC13C5E8A88/projects/etagi/.venv/lib/python3.11/site-packages/requests/__init__.py'>

  File "/mnt/E83C5EC13C5E8A88/projects/etagi/.venv/lib/python3.11/site-packages/requests/api.py", line 73, in get
    return request("get", url, params=params, **kwargs)
           │              │           │         └ {'headers': {'Host': 'krisha.kz', 'User-Agent': 'Mozilla/5.0 (X11; Ubuntu; Linux x86_64; rv:109.0) Gecko/20100101 Firefox/119...
           │              │           └ None
           │              └ 'https://krisha.kz/a/ajaxGetSearchNbResults?search-url=/arenda/kvartiry/almaty/?das[map.complex]=7&isOnMap=0'
           └ <function request at 0x7fb0ccf59bc0>
  File "/mnt/E83C5EC13C5E8A88/projects/etagi/.venv/lib/python3.11/site-packages/requests/api.py", line 59, in request
    return session.request(method=method, url=url, **kwargs)
           │       │              │           │      └ {'params': None, 'headers': {'Host': 'krisha.kz', 'User-Agent': 'Mozilla/5.0 (X11; Ubuntu; Linux x86_64; rv:109.0) Gecko/2010...
           │       │              │           └ 'https://krisha.kz/a/ajaxGetSearchNbResults?search-url=/arenda/kvartiry/almaty/?das[map.complex]=7&isOnMap=0'
           │       │              └ 'get'
           │       └ <function Session.request at 0x7fb0ccfadd00>
           └ <requests.sessions.Session object at 0x7fb0cb856bd0>
  File "/mnt/E83C5EC13C5E8A88/projects/etagi/.venv/lib/python3.11/site-packages/requests/sessions.py", line 589, in request
    resp = self.send(prep, **send_kwargs)
           │    │    │       └ {'timeout': None, 'allow_redirects': True, 'proxies': OrderedDict(), 'stream': False, 'verify': True, 'cert': None}
           │    │    └ <PreparedRequest [GET]>
           │    └ <function Session.send at 0x7fb0ccfae200>
           └ <requests.sessions.Session object at 0x7fb0cb856bd0>
  File "/mnt/E83C5EC13C5E8A88/projects/etagi/.venv/lib/python3.11/site-packages/requests/sessions.py", line 703, in send
    r = adapter.send(request, **kwargs)
        │       │    │          └ {'timeout': None, 'proxies': OrderedDict(), 'stream': False, 'verify': True, 'cert': None}
        │       │    └ <PreparedRequest [GET]>
        │       └ <function HTTPAdapter.send at 0x7fb0ccfad580>
        └ <requests.adapters.HTTPAdapter object at 0x7fb0cb857b10>
  File "/mnt/E83C5EC13C5E8A88/projects/etagi/.venv/lib/python3.11/site-packages/requests/adapters.py", line 519, in send
    raise ConnectionError(e, request=request)
          │                          └ <PreparedRequest [GET]>
          └ <class 'requests.exceptions.ConnectionError'>

requests.exceptions.ConnectionError: HTTPSConnectionPool(host='krisha.kz', port=443): Max retries exceeded with url: /a/ajaxGetSearchNbResults?search-url=/arenda/kvartiry/almaty/?das%5Bmap.complex%5D=7&isOnMap=0 (Caused by NewConnectionError('<urllib3.connection.HTTPSConnection object at 0x7fb0cb854250>: Failed to establish a new connection: Error connecting to SOCKS5 proxy localhost:9150: [Errno 111] Connection refused'))
2024-02-10 17:06:10.098 | ERROR    | __main__:parse_data:87 - error
Traceback (most recent call last):

  File "/mnt/E83C5EC13C5E8A88/projects/etagi/.venv/lib/python3.11/site-packages/socks.py", line 787, in connect
    super(socksocket, self).connect(proxy_addr)
          │           │             └ 'localhost'
          │           └ <socks.socksocket [closed] fd=-1, family=2, type=1, proto=6>
          └ <class 'socks.socksocket'>

ConnectionRefusedError: [Errno 111] Connection refused


During handling of the above exception, another exception occurred:


Traceback (most recent call last):

  File "/mnt/E83C5EC13C5E8A88/projects/etagi/.venv/lib/python3.11/site-packages/urllib3/connection.py", line 198, in _new_conn
    sock = connection.create_connection(
           │          └ <function create_connection at 0x7fb0cdb854e0>
           └ <module 'urllib3.util.connection' from '/mnt/E83C5EC13C5E8A88/projects/etagi/.venv/lib/python3.11/site-packages/urllib3/util/...
  File "/mnt/E83C5EC13C5E8A88/projects/etagi/.venv/lib/python3.11/site-packages/urllib3/util/connection.py", line 85, in create_connection
    raise err
          └ None
  File "/mnt/E83C5EC13C5E8A88/projects/etagi/.venv/lib/python3.11/site-packages/urllib3/util/connection.py", line 73, in create_connection
    sock.connect(sa)
    │    │       └ ('185.143.129.90', 443)
    │    └ <function socksocket.connect at 0x7fb0ccfac860>
    └ <socks.socksocket [closed] fd=-1, family=2, type=1, proto=6>
  File "/mnt/E83C5EC13C5E8A88/projects/etagi/.venv/lib/python3.11/site-packages/socks.py", line 47, in wrapper
    return function(*args, **kwargs)
           │         │       └ {}
           │         └ (<socks.socksocket [closed] fd=-1, family=2, type=1, proto=6>, ('185.143.129.90', 443))
           └ <function socksocket.connect at 0x7fb0ccfac7c0>
  File "/mnt/E83C5EC13C5E8A88/projects/etagi/.venv/lib/python3.11/site-packages/socks.py", line 800, in connect
    raise ProxyConnectionError(msg, error)
          │                    └ 'Error connecting to SOCKS5 proxy localhost:9150'
          └ <class 'socks.ProxyConnectionError'>

socks.ProxyConnectionError: Error connecting to SOCKS5 proxy localhost:9150: [Errno 111] Connection refused


The above exception was the direct cause of the following exception:


Traceback (most recent call last):

  File "/mnt/E83C5EC13C5E8A88/projects/etagi/.venv/lib/python3.11/site-packages/urllib3/connectionpool.py", line 793, in urlopen
    response = self._make_request(
               │    └ <function HTTPConnectionPool._make_request at 0x7fb0cd3b8fe0>
               └ <urllib3.connectionpool.HTTPSConnectionPool object at 0x7fb0cb8544d0>
  File "/mnt/E83C5EC13C5E8A88/projects/etagi/.venv/lib/python3.11/site-packages/urllib3/connectionpool.py", line 491, in _make_request
    raise new_e
          └ NewConnectionError('<urllib3.connection.HTTPSConnection object at 0x7fb0cb855910>: Failed to establish a new connection: Erro...
  File "/mnt/E83C5EC13C5E8A88/projects/etagi/.venv/lib/python3.11/site-packages/urllib3/connectionpool.py", line 467, in _make_request
    self._validate_conn(conn)
    │    │              └ <urllib3.connection.HTTPSConnection object at 0x7fb0cb855910>
    │    └ <function HTTPSConnectionPool._validate_conn at 0x7fb0cd3b9580>
    └ <urllib3.connectionpool.HTTPSConnectionPool object at 0x7fb0cb8544d0>
  File "/mnt/E83C5EC13C5E8A88/projects/etagi/.venv/lib/python3.11/site-packages/urllib3/connectionpool.py", line 1099, in _validate_conn
    conn.connect()
    │    └ <function HTTPSConnection.connect at 0x7fb0cd3a1260>
    └ <urllib3.connection.HTTPSConnection object at 0x7fb0cb855910>
  File "/mnt/E83C5EC13C5E8A88/projects/etagi/.venv/lib/python3.11/site-packages/urllib3/connection.py", line 616, in connect
    self.sock = sock = self._new_conn()
    │    │             │    └ <function HTTPConnection._new_conn at 0x7fb0cd3a0900>
    │    │             └ <urllib3.connection.HTTPSConnection object at 0x7fb0cb855910>
    │    └ None
    └ <urllib3.connection.HTTPSConnection object at 0x7fb0cb855910>
  File "/mnt/E83C5EC13C5E8A88/projects/etagi/.venv/lib/python3.11/site-packages/urllib3/connection.py", line 213, in _new_conn
    raise NewConnectionError(
          └ <class 'urllib3.exceptions.NewConnectionError'>

urllib3.exceptions.NewConnectionError: <urllib3.connection.HTTPSConnection object at 0x7fb0cb855910>: Failed to establish a new connection: Error connecting to SOCKS5 proxy localhost:9150: [Errno 111] Connection refused


The above exception was the direct cause of the following exception:


Traceback (most recent call last):

  File "/mnt/E83C5EC13C5E8A88/projects/etagi/.venv/lib/python3.11/site-packages/requests/adapters.py", line 486, in send
    resp = conn.urlopen(
           │    └ <function HTTPConnectionPool.urlopen at 0x7fb0cd3b91c0>
           └ <urllib3.connectionpool.HTTPSConnectionPool object at 0x7fb0cb8544d0>
  File "/mnt/E83C5EC13C5E8A88/projects/etagi/.venv/lib/python3.11/site-packages/urllib3/connectionpool.py", line 847, in urlopen
    retries = retries.increment(
              │       └ <function Retry.increment at 0x7fb0cd318040>
              └ Retry(total=0, connect=None, read=False, redirect=None, status=None)
  File "/mnt/E83C5EC13C5E8A88/projects/etagi/.venv/lib/python3.11/site-packages/urllib3/util/retry.py", line 515, in increment
    raise MaxRetryError(_pool, url, reason) from reason  # type: ignore[arg-type]
          │             │      │    │            └ NewConnectionError('<urllib3.connection.HTTPSConnection object at 0x7fb0cb855910>: Failed to establish a new connection: Erro...
          │             │      │    └ NewConnectionError('<urllib3.connection.HTTPSConnection object at 0x7fb0cb855910>: Failed to establish a new connection: Erro...
          │             │      └ '/a/ajaxGetSearchNbResults?search-url=/arenda/kvartiry/almaty/?das%5Bmap.complex%5D=8&isOnMap=0'
          │             └ <urllib3.connectionpool.HTTPSConnectionPool object at 0x7fb0cb8544d0>
          └ <class 'urllib3.exceptions.MaxRetryError'>

urllib3.exceptions.MaxRetryError: HTTPSConnectionPool(host='krisha.kz', port=443): Max retries exceeded with url: /a/ajaxGetSearchNbResults?search-url=/arenda/kvartiry/almaty/?das%5Bmap.complex%5D=8&isOnMap=0 (Caused by NewConnectionError('<urllib3.connection.HTTPSConnection object at 0x7fb0cb855910>: Failed to establish a new connection: Error connecting to SOCKS5 proxy localhost:9150: [Errno 111] Connection refused'))


During handling of the above exception, another exception occurred:


Traceback (most recent call last):

  File "/mnt/E83C5EC13C5E8A88/projects/etagi/nb_parser.py", line 92, in <module>
    parse_data()
    └ <function parse_data at 0x7fb0cb979bc0>

> File "/mnt/E83C5EC13C5E8A88/projects/etagi/nb_parser.py", line 61, in parse_data
    r = requests.get(url=querry.format(str(i)), headers=headers)
        │        │       │      │          │            └ {'Host': 'krisha.kz', 'User-Agent': 'Mozilla/5.0 (X11; Ubuntu; Linux x86_64; rv:109.0) Gecko/20100101 Firefox/119.0', 'Accept...
        │        │       │      │          └ 8
        │        │       │      └ <method 'format' of 'str' objects>
        │        │       └ 'https://krisha.kz/a/ajaxGetSearchNbResults?search-url=/arenda/kvartiry/almaty/?das[map.complex]={}&isOnMap=0'
        │        └ <function get at 0x7fb0ccf42ac0>
        └ <module 'requests' from '/mnt/E83C5EC13C5E8A88/projects/etagi/.venv/lib/python3.11/site-packages/requests/__init__.py'>

  File "/mnt/E83C5EC13C5E8A88/projects/etagi/.venv/lib/python3.11/site-packages/requests/api.py", line 73, in get
    return request("get", url, params=params, **kwargs)
           │              │           │         └ {'headers': {'Host': 'krisha.kz', 'User-Agent': 'Mozilla/5.0 (X11; Ubuntu; Linux x86_64; rv:109.0) Gecko/20100101 Firefox/119...
           │              │           └ None
           │              └ 'https://krisha.kz/a/ajaxGetSearchNbResults?search-url=/arenda/kvartiry/almaty/?das[map.complex]=8&isOnMap=0'
           └ <function request at 0x7fb0ccf59bc0>
  File "/mnt/E83C5EC13C5E8A88/projects/etagi/.venv/lib/python3.11/site-packages/requests/api.py", line 59, in request
    return session.request(method=method, url=url, **kwargs)
           │       │              │           │      └ {'params': None, 'headers': {'Host': 'krisha.kz', 'User-Agent': 'Mozilla/5.0 (X11; Ubuntu; Linux x86_64; rv:109.0) Gecko/2010...
           │       │              │           └ 'https://krisha.kz/a/ajaxGetSearchNbResults?search-url=/arenda/kvartiry/almaty/?das[map.complex]=8&isOnMap=0'
           │       │              └ 'get'
           │       └ <function Session.request at 0x7fb0ccfadd00>
           └ <requests.sessions.Session object at 0x7fb0cb854150>
  File "/mnt/E83C5EC13C5E8A88/projects/etagi/.venv/lib/python3.11/site-packages/requests/sessions.py", line 589, in request
    resp = self.send(prep, **send_kwargs)
           │    │    │       └ {'timeout': None, 'allow_redirects': True, 'proxies': OrderedDict(), 'stream': False, 'verify': True, 'cert': None}
           │    │    └ <PreparedRequest [GET]>
           │    └ <function Session.send at 0x7fb0ccfae200>
           └ <requests.sessions.Session object at 0x7fb0cb854150>
  File "/mnt/E83C5EC13C5E8A88/projects/etagi/.venv/lib/python3.11/site-packages/requests/sessions.py", line 703, in send
    r = adapter.send(request, **kwargs)
        │       │    │          └ {'timeout': None, 'proxies': OrderedDict(), 'stream': False, 'verify': True, 'cert': None}
        │       │    └ <PreparedRequest [GET]>
        │       └ <function HTTPAdapter.send at 0x7fb0ccfad580>
        └ <requests.adapters.HTTPAdapter object at 0x7fb0cb855f50>
  File "/mnt/E83C5EC13C5E8A88/projects/etagi/.venv/lib/python3.11/site-packages/requests/adapters.py", line 519, in send
    raise ConnectionError(e, request=request)
          │                          └ <PreparedRequest [GET]>
          └ <class 'requests.exceptions.ConnectionError'>

requests.exceptions.ConnectionError: HTTPSConnectionPool(host='krisha.kz', port=443): Max retries exceeded with url: /a/ajaxGetSearchNbResults?search-url=/arenda/kvartiry/almaty/?das%5Bmap.complex%5D=8&isOnMap=0 (Caused by NewConnectionError('<urllib3.connection.HTTPSConnection object at 0x7fb0cb855910>: Failed to establish a new connection: Error connecting to SOCKS5 proxy localhost:9150: [Errno 111] Connection refused'))
2024-02-10 17:06:10.122 | ERROR    | __main__:parse_data:87 - error
Traceback (most recent call last):

  File "/mnt/E83C5EC13C5E8A88/projects/etagi/.venv/lib/python3.11/site-packages/socks.py", line 787, in connect
    super(socksocket, self).connect(proxy_addr)
          │           │             └ 'localhost'
          │           └ <socks.socksocket [closed] fd=-1, family=2, type=1, proto=6>
          └ <class 'socks.socksocket'>

ConnectionRefusedError: [Errno 111] Connection refused


During handling of the above exception, another exception occurred:


Traceback (most recent call last):

  File "/mnt/E83C5EC13C5E8A88/projects/etagi/.venv/lib/python3.11/site-packages/urllib3/connection.py", line 198, in _new_conn
    sock = connection.create_connection(
           │          └ <function create_connection at 0x7fb0cdb854e0>
           └ <module 'urllib3.util.connection' from '/mnt/E83C5EC13C5E8A88/projects/etagi/.venv/lib/python3.11/site-packages/urllib3/util/...
  File "/mnt/E83C5EC13C5E8A88/projects/etagi/.venv/lib/python3.11/site-packages/urllib3/util/connection.py", line 85, in create_connection
    raise err
          └ None
  File "/mnt/E83C5EC13C5E8A88/projects/etagi/.venv/lib/python3.11/site-packages/urllib3/util/connection.py", line 73, in create_connection
    sock.connect(sa)
    │    │       └ ('185.143.129.90', 443)
    │    └ <function socksocket.connect at 0x7fb0ccfac860>
    └ <socks.socksocket [closed] fd=-1, family=2, type=1, proto=6>
  File "/mnt/E83C5EC13C5E8A88/projects/etagi/.venv/lib/python3.11/site-packages/socks.py", line 47, in wrapper
    return function(*args, **kwargs)
           │         │       └ {}
           │         └ (<socks.socksocket [closed] fd=-1, family=2, type=1, proto=6>, ('185.143.129.90', 443))
           └ <function socksocket.connect at 0x7fb0ccfac7c0>
  File "/mnt/E83C5EC13C5E8A88/projects/etagi/.venv/lib/python3.11/site-packages/socks.py", line 800, in connect
    raise ProxyConnectionError(msg, error)
          │                    └ 'Error connecting to SOCKS5 proxy localhost:9150'
          └ <class 'socks.ProxyConnectionError'>

socks.ProxyConnectionError: Error connecting to SOCKS5 proxy localhost:9150: [Errno 111] Connection refused


The above exception was the direct cause of the following exception:


Traceback (most recent call last):

  File "/mnt/E83C5EC13C5E8A88/projects/etagi/.venv/lib/python3.11/site-packages/urllib3/connectionpool.py", line 793, in urlopen
    response = self._make_request(
               │    └ <function HTTPConnectionPool._make_request at 0x7fb0cd3b8fe0>
               └ <urllib3.connectionpool.HTTPSConnectionPool object at 0x7fb0cb9bf150>
  File "/mnt/E83C5EC13C5E8A88/projects/etagi/.venv/lib/python3.11/site-packages/urllib3/connectionpool.py", line 491, in _make_request
    raise new_e
          └ NewConnectionError('<urllib3.connection.HTTPSConnection object at 0x7fb0cb9e8910>: Failed to establish a new connection: Erro...
  File "/mnt/E83C5EC13C5E8A88/projects/etagi/.venv/lib/python3.11/site-packages/urllib3/connectionpool.py", line 467, in _make_request
    self._validate_conn(conn)
    │    │              └ <urllib3.connection.HTTPSConnection object at 0x7fb0cb9e8910>
    │    └ <function HTTPSConnectionPool._validate_conn at 0x7fb0cd3b9580>
    └ <urllib3.connectionpool.HTTPSConnectionPool object at 0x7fb0cb9bf150>
  File "/mnt/E83C5EC13C5E8A88/projects/etagi/.venv/lib/python3.11/site-packages/urllib3/connectionpool.py", line 1099, in _validate_conn
    conn.connect()
    │    └ <function HTTPSConnection.connect at 0x7fb0cd3a1260>
    └ <urllib3.connection.HTTPSConnection object at 0x7fb0cb9e8910>
  File "/mnt/E83C5EC13C5E8A88/projects/etagi/.venv/lib/python3.11/site-packages/urllib3/connection.py", line 616, in connect
    self.sock = sock = self._new_conn()
    │    │             │    └ <function HTTPConnection._new_conn at 0x7fb0cd3a0900>
    │    │             └ <urllib3.connection.HTTPSConnection object at 0x7fb0cb9e8910>
    │    └ None
    └ <urllib3.connection.HTTPSConnection object at 0x7fb0cb9e8910>
  File "/mnt/E83C5EC13C5E8A88/projects/etagi/.venv/lib/python3.11/site-packages/urllib3/connection.py", line 213, in _new_conn
    raise NewConnectionError(
          └ <class 'urllib3.exceptions.NewConnectionError'>

urllib3.exceptions.NewConnectionError: <urllib3.connection.HTTPSConnection object at 0x7fb0cb9e8910>: Failed to establish a new connection: Error connecting to SOCKS5 proxy localhost:9150: [Errno 111] Connection refused


The above exception was the direct cause of the following exception:


Traceback (most recent call last):

  File "/mnt/E83C5EC13C5E8A88/projects/etagi/.venv/lib/python3.11/site-packages/requests/adapters.py", line 486, in send
    resp = conn.urlopen(
           │    └ <function HTTPConnectionPool.urlopen at 0x7fb0cd3b91c0>
           └ <urllib3.connectionpool.HTTPSConnectionPool object at 0x7fb0cb9bf150>
  File "/mnt/E83C5EC13C5E8A88/projects/etagi/.venv/lib/python3.11/site-packages/urllib3/connectionpool.py", line 847, in urlopen
    retries = retries.increment(
              │       └ <function Retry.increment at 0x7fb0cd318040>
              └ Retry(total=0, connect=None, read=False, redirect=None, status=None)
  File "/mnt/E83C5EC13C5E8A88/projects/etagi/.venv/lib/python3.11/site-packages/urllib3/util/retry.py", line 515, in increment
    raise MaxRetryError(_pool, url, reason) from reason  # type: ignore[arg-type]
          │             │      │    │            └ NewConnectionError('<urllib3.connection.HTTPSConnection object at 0x7fb0cb9e8910>: Failed to establish a new connection: Erro...
          │             │      │    └ NewConnectionError('<urllib3.connection.HTTPSConnection object at 0x7fb0cb9e8910>: Failed to establish a new connection: Erro...
          │             │      └ '/a/ajaxGetSearchNbResults?search-url=/arenda/kvartiry/almaty/?das%5Bmap.complex%5D=9&isOnMap=0'
          │             └ <urllib3.connectionpool.HTTPSConnectionPool object at 0x7fb0cb9bf150>
          └ <class 'urllib3.exceptions.MaxRetryError'>

urllib3.exceptions.MaxRetryError: HTTPSConnectionPool(host='krisha.kz', port=443): Max retries exceeded with url: /a/ajaxGetSearchNbResults?search-url=/arenda/kvartiry/almaty/?das%5Bmap.complex%5D=9&isOnMap=0 (Caused by NewConnectionError('<urllib3.connection.HTTPSConnection object at 0x7fb0cb9e8910>: Failed to establish a new connection: Error connecting to SOCKS5 proxy localhost:9150: [Errno 111] Connection refused'))


During handling of the above exception, another exception occurred:


Traceback (most recent call last):

  File "/mnt/E83C5EC13C5E8A88/projects/etagi/nb_parser.py", line 92, in <module>
    parse_data()
    └ <function parse_data at 0x7fb0cb979bc0>

> File "/mnt/E83C5EC13C5E8A88/projects/etagi/nb_parser.py", line 61, in parse_data
    r = requests.get(url=querry.format(str(i)), headers=headers)
        │        │       │      │          │            └ {'Host': 'krisha.kz', 'User-Agent': 'Mozilla/5.0 (X11; Ubuntu; Linux x86_64; rv:109.0) Gecko/20100101 Firefox/119.0', 'Accept...
        │        │       │      │          └ 9
        │        │       │      └ <method 'format' of 'str' objects>
        │        │       └ 'https://krisha.kz/a/ajaxGetSearchNbResults?search-url=/arenda/kvartiry/almaty/?das[map.complex]={}&isOnMap=0'
        │        └ <function get at 0x7fb0ccf42ac0>
        └ <module 'requests' from '/mnt/E83C5EC13C5E8A88/projects/etagi/.venv/lib/python3.11/site-packages/requests/__init__.py'>

  File "/mnt/E83C5EC13C5E8A88/projects/etagi/.venv/lib/python3.11/site-packages/requests/api.py", line 73, in get
    return request("get", url, params=params, **kwargs)
           │              │           │         └ {'headers': {'Host': 'krisha.kz', 'User-Agent': 'Mozilla/5.0 (X11; Ubuntu; Linux x86_64; rv:109.0) Gecko/20100101 Firefox/119...
           │              │           └ None
           │              └ 'https://krisha.kz/a/ajaxGetSearchNbResults?search-url=/arenda/kvartiry/almaty/?das[map.complex]=9&isOnMap=0'
           └ <function request at 0x7fb0ccf59bc0>
  File "/mnt/E83C5EC13C5E8A88/projects/etagi/.venv/lib/python3.11/site-packages/requests/api.py", line 59, in request
    return session.request(method=method, url=url, **kwargs)
           │       │              │           │      └ {'params': None, 'headers': {'Host': 'krisha.kz', 'User-Agent': 'Mozilla/5.0 (X11; Ubuntu; Linux x86_64; rv:109.0) Gecko/2010...
           │       │              │           └ 'https://krisha.kz/a/ajaxGetSearchNbResults?search-url=/arenda/kvartiry/almaty/?das[map.complex]=9&isOnMap=0'
           │       │              └ 'get'
           │       └ <function Session.request at 0x7fb0ccfadd00>
           └ <requests.sessions.Session object at 0x7fb0cdc37a90>
  File "/mnt/E83C5EC13C5E8A88/projects/etagi/.venv/lib/python3.11/site-packages/requests/sessions.py", line 589, in request
    resp = self.send(prep, **send_kwargs)
           │    │    │       └ {'timeout': None, 'allow_redirects': True, 'proxies': OrderedDict(), 'stream': False, 'verify': True, 'cert': None}
           │    │    └ <PreparedRequest [GET]>
           │    └ <function Session.send at 0x7fb0ccfae200>
           └ <requests.sessions.Session object at 0x7fb0cdc37a90>
  File "/mnt/E83C5EC13C5E8A88/projects/etagi/.venv/lib/python3.11/site-packages/requests/sessions.py", line 703, in send
    r = adapter.send(request, **kwargs)
        │       │    │          └ {'timeout': None, 'proxies': OrderedDict(), 'stream': False, 'verify': True, 'cert': None}
        │       │    └ <PreparedRequest [GET]>
        │       └ <function HTTPAdapter.send at 0x7fb0ccfad580>
        └ <requests.adapters.HTTPAdapter object at 0x7fb0cb9eea50>
  File "/mnt/E83C5EC13C5E8A88/projects/etagi/.venv/lib/python3.11/site-packages/requests/adapters.py", line 519, in send
    raise ConnectionError(e, request=request)
          │                          └ <PreparedRequest [GET]>
          └ <class 'requests.exceptions.ConnectionError'>

requests.exceptions.ConnectionError: HTTPSConnectionPool(host='krisha.kz', port=443): Max retries exceeded with url: /a/ajaxGetSearchNbResults?search-url=/arenda/kvartiry/almaty/?das%5Bmap.complex%5D=9&isOnMap=0 (Caused by NewConnectionError('<urllib3.connection.HTTPSConnection object at 0x7fb0cb9e8910>: Failed to establish a new connection: Error connecting to SOCKS5 proxy localhost:9150: [Errno 111] Connection refused'))
2024-02-10 17:06:10.145 | ERROR    | __main__:parse_data:87 - error
Traceback (most recent call last):

  File "/mnt/E83C5EC13C5E8A88/projects/etagi/.venv/lib/python3.11/site-packages/socks.py", line 787, in connect
    super(socksocket, self).connect(proxy_addr)
          │           │             └ 'localhost'
          │           └ <socks.socksocket [closed] fd=-1, family=2, type=1, proto=6>
          └ <class 'socks.socksocket'>

ConnectionRefusedError: [Errno 111] Connection refused


During handling of the above exception, another exception occurred:


Traceback (most recent call last):

  File "/mnt/E83C5EC13C5E8A88/projects/etagi/.venv/lib/python3.11/site-packages/urllib3/connection.py", line 198, in _new_conn
    sock = connection.create_connection(
           │          └ <function create_connection at 0x7fb0cdb854e0>
           └ <module 'urllib3.util.connection' from '/mnt/E83C5EC13C5E8A88/projects/etagi/.venv/lib/python3.11/site-packages/urllib3/util/...
  File "/mnt/E83C5EC13C5E8A88/projects/etagi/.venv/lib/python3.11/site-packages/urllib3/util/connection.py", line 85, in create_connection
    raise err
          └ None
  File "/mnt/E83C5EC13C5E8A88/projects/etagi/.venv/lib/python3.11/site-packages/urllib3/util/connection.py", line 73, in create_connection
    sock.connect(sa)
    │    │       └ ('185.143.129.90', 443)
    │    └ <function socksocket.connect at 0x7fb0ccfac860>
    └ <socks.socksocket [closed] fd=-1, family=2, type=1, proto=6>
  File "/mnt/E83C5EC13C5E8A88/projects/etagi/.venv/lib/python3.11/site-packages/socks.py", line 47, in wrapper
    return function(*args, **kwargs)
           │         │       └ {}
           │         └ (<socks.socksocket [closed] fd=-1, family=2, type=1, proto=6>, ('185.143.129.90', 443))
           └ <function socksocket.connect at 0x7fb0ccfac7c0>
  File "/mnt/E83C5EC13C5E8A88/projects/etagi/.venv/lib/python3.11/site-packages/socks.py", line 800, in connect
    raise ProxyConnectionError(msg, error)
          │                    └ 'Error connecting to SOCKS5 proxy localhost:9150'
          └ <class 'socks.ProxyConnectionError'>

socks.ProxyConnectionError: Error connecting to SOCKS5 proxy localhost:9150: [Errno 111] Connection refused


The above exception was the direct cause of the following exception:


Traceback (most recent call last):

  File "/mnt/E83C5EC13C5E8A88/projects/etagi/.venv/lib/python3.11/site-packages/urllib3/connectionpool.py", line 793, in urlopen
    response = self._make_request(
               │    └ <function HTTPConnectionPool._make_request at 0x7fb0cd3b8fe0>
               └ <urllib3.connectionpool.HTTPSConnectionPool object at 0x7fb0cb860910>
  File "/mnt/E83C5EC13C5E8A88/projects/etagi/.venv/lib/python3.11/site-packages/urllib3/connectionpool.py", line 491, in _make_request
    raise new_e
          └ NewConnectionError('<urllib3.connection.HTTPSConnection object at 0x7fb0cb8635d0>: Failed to establish a new connection: Erro...
  File "/mnt/E83C5EC13C5E8A88/projects/etagi/.venv/lib/python3.11/site-packages/urllib3/connectionpool.py", line 467, in _make_request
    self._validate_conn(conn)
    │    │              └ <urllib3.connection.HTTPSConnection object at 0x7fb0cb8635d0>
    │    └ <function HTTPSConnectionPool._validate_conn at 0x7fb0cd3b9580>
    └ <urllib3.connectionpool.HTTPSConnectionPool object at 0x7fb0cb860910>
  File "/mnt/E83C5EC13C5E8A88/projects/etagi/.venv/lib/python3.11/site-packages/urllib3/connectionpool.py", line 1099, in _validate_conn
    conn.connect()
    │    └ <function HTTPSConnection.connect at 0x7fb0cd3a1260>
    └ <urllib3.connection.HTTPSConnection object at 0x7fb0cb8635d0>
  File "/mnt/E83C5EC13C5E8A88/projects/etagi/.venv/lib/python3.11/site-packages/urllib3/connection.py", line 616, in connect
    self.sock = sock = self._new_conn()
    │    │             │    └ <function HTTPConnection._new_conn at 0x7fb0cd3a0900>
    │    │             └ <urllib3.connection.HTTPSConnection object at 0x7fb0cb8635d0>
    │    └ None
    └ <urllib3.connection.HTTPSConnection object at 0x7fb0cb8635d0>
  File "/mnt/E83C5EC13C5E8A88/projects/etagi/.venv/lib/python3.11/site-packages/urllib3/connection.py", line 213, in _new_conn
    raise NewConnectionError(
          └ <class 'urllib3.exceptions.NewConnectionError'>

urllib3.exceptions.NewConnectionError: <urllib3.connection.HTTPSConnection object at 0x7fb0cb8635d0>: Failed to establish a new connection: Error connecting to SOCKS5 proxy localhost:9150: [Errno 111] Connection refused


The above exception was the direct cause of the following exception:


Traceback (most recent call last):

  File "/mnt/E83C5EC13C5E8A88/projects/etagi/.venv/lib/python3.11/site-packages/requests/adapters.py", line 486, in send
    resp = conn.urlopen(
           │    └ <function HTTPConnectionPool.urlopen at 0x7fb0cd3b91c0>
           └ <urllib3.connectionpool.HTTPSConnectionPool object at 0x7fb0cb860910>
  File "/mnt/E83C5EC13C5E8A88/projects/etagi/.venv/lib/python3.11/site-packages/urllib3/connectionpool.py", line 847, in urlopen
    retries = retries.increment(
              │       └ <function Retry.increment at 0x7fb0cd318040>
              └ Retry(total=0, connect=None, read=False, redirect=None, status=None)
  File "/mnt/E83C5EC13C5E8A88/projects/etagi/.venv/lib/python3.11/site-packages/urllib3/util/retry.py", line 515, in increment
    raise MaxRetryError(_pool, url, reason) from reason  # type: ignore[arg-type]
          │             │      │    │            └ NewConnectionError('<urllib3.connection.HTTPSConnection object at 0x7fb0cb8635d0>: Failed to establish a new connection: Erro...
          │             │      │    └ NewConnectionError('<urllib3.connection.HTTPSConnection object at 0x7fb0cb8635d0>: Failed to establish a new connection: Erro...
          │             │      └ '/a/ajaxGetSearchNbResults?search-url=/arenda/kvartiry/almaty/?das%5Bmap.complex%5D=10&isOnMap=0'
          │             └ <urllib3.connectionpool.HTTPSConnectionPool object at 0x7fb0cb860910>
          └ <class 'urllib3.exceptions.MaxRetryError'>

urllib3.exceptions.MaxRetryError: HTTPSConnectionPool(host='krisha.kz', port=443): Max retries exceeded with url: /a/ajaxGetSearchNbResults?search-url=/arenda/kvartiry/almaty/?das%5Bmap.complex%5D=10&isOnMap=0 (Caused by NewConnectionError('<urllib3.connection.HTTPSConnection object at 0x7fb0cb8635d0>: Failed to establish a new connection: Error connecting to SOCKS5 proxy localhost:9150: [Errno 111] Connection refused'))


During handling of the above exception, another exception occurred:


Traceback (most recent call last):

  File "/mnt/E83C5EC13C5E8A88/projects/etagi/nb_parser.py", line 92, in <module>
    parse_data()
    └ <function parse_data at 0x7fb0cb979bc0>

> File "/mnt/E83C5EC13C5E8A88/projects/etagi/nb_parser.py", line 61, in parse_data
    r = requests.get(url=querry.format(str(i)), headers=headers)
        │        │       │      │          │            └ {'Host': 'krisha.kz', 'User-Agent': 'Mozilla/5.0 (X11; Ubuntu; Linux x86_64; rv:109.0) Gecko/20100101 Firefox/119.0', 'Accept...
        │        │       │      │          └ 10
        │        │       │      └ <method 'format' of 'str' objects>
        │        │       └ 'https://krisha.kz/a/ajaxGetSearchNbResults?search-url=/arenda/kvartiry/almaty/?das[map.complex]={}&isOnMap=0'
        │        └ <function get at 0x7fb0ccf42ac0>
        └ <module 'requests' from '/mnt/E83C5EC13C5E8A88/projects/etagi/.venv/lib/python3.11/site-packages/requests/__init__.py'>

  File "/mnt/E83C5EC13C5E8A88/projects/etagi/.venv/lib/python3.11/site-packages/requests/api.py", line 73, in get
    return request("get", url, params=params, **kwargs)
           │              │           │         └ {'headers': {'Host': 'krisha.kz', 'User-Agent': 'Mozilla/5.0 (X11; Ubuntu; Linux x86_64; rv:109.0) Gecko/20100101 Firefox/119...
           │              │           └ None
           │              └ 'https://krisha.kz/a/ajaxGetSearchNbResults?search-url=/arenda/kvartiry/almaty/?das[map.complex]=10&isOnMap=0'
           └ <function request at 0x7fb0ccf59bc0>
  File "/mnt/E83C5EC13C5E8A88/projects/etagi/.venv/lib/python3.11/site-packages/requests/api.py", line 59, in request
    return session.request(method=method, url=url, **kwargs)
           │       │              │           │      └ {'params': None, 'headers': {'Host': 'krisha.kz', 'User-Agent': 'Mozilla/5.0 (X11; Ubuntu; Linux x86_64; rv:109.0) Gecko/2010...
           │       │              │           └ 'https://krisha.kz/a/ajaxGetSearchNbResults?search-url=/arenda/kvartiry/almaty/?das[map.complex]=10&isOnMap=0'
           │       │              └ 'get'
           │       └ <function Session.request at 0x7fb0ccfadd00>
           └ <requests.sessions.Session object at 0x7fb0cb9d7ad0>
  File "/mnt/E83C5EC13C5E8A88/projects/etagi/.venv/lib/python3.11/site-packages/requests/sessions.py", line 589, in request
    resp = self.send(prep, **send_kwargs)
           │    │    │       └ {'timeout': None, 'allow_redirects': True, 'proxies': OrderedDict(), 'stream': False, 'verify': True, 'cert': None}
           │    │    └ <PreparedRequest [GET]>
           │    └ <function Session.send at 0x7fb0ccfae200>
           └ <requests.sessions.Session object at 0x7fb0cb9d7ad0>
  File "/mnt/E83C5EC13C5E8A88/projects/etagi/.venv/lib/python3.11/site-packages/requests/sessions.py", line 703, in send
    r = adapter.send(request, **kwargs)
        │       │    │          └ {'timeout': None, 'proxies': OrderedDict(), 'stream': False, 'verify': True, 'cert': None}
        │       │    └ <PreparedRequest [GET]>
        │       └ <function HTTPAdapter.send at 0x7fb0ccfad580>
        └ <requests.adapters.HTTPAdapter object at 0x7fb0cb9e8d50>
  File "/mnt/E83C5EC13C5E8A88/projects/etagi/.venv/lib/python3.11/site-packages/requests/adapters.py", line 519, in send
    raise ConnectionError(e, request=request)
          │                          └ <PreparedRequest [GET]>
          └ <class 'requests.exceptions.ConnectionError'>

requests.exceptions.ConnectionError: HTTPSConnectionPool(host='krisha.kz', port=443): Max retries exceeded with url: /a/ajaxGetSearchNbResults?search-url=/arenda/kvartiry/almaty/?das%5Bmap.complex%5D=10&isOnMap=0 (Caused by NewConnectionError('<urllib3.connection.HTTPSConnection object at 0x7fb0cb8635d0>: Failed to establish a new connection: Error connecting to SOCKS5 proxy localhost:9150: [Errno 111] Connection refused'))
2024-02-13 23:45:35.031 | ERROR    | __main__:parse_data:95 - error
Traceback (most recent call last):

  File "/mnt/E83C5EC13C5E8A88/projects/go-table-editor/parser/./nb_parser.py", line 104, in <module>
    parse_data()
    └ <function parse_data at 0x7fb4264b84a0>

> File "/mnt/E83C5EC13C5E8A88/projects/go-table-editor/parser/./nb_parser.py", line 83, in parse_data
    d = dists.get_dist(csrf.lower().strip())
        │     │        │    └ <method 'lower' of 'str' objects>
        │     │        └ ' Abay Residence '
        │     └ <function district_manager.get_dist at 0x7fb42768f4c0>
        └ <districts.district_manager object at 0x7fb4289ed950>

  File "/mnt/E83C5EC13C5E8A88/projects/go-table-editor/parser/districts.py", line 48, in get_dist
    if a[1] <= 80:
       └ None

TypeError: 'NoneType' object is not subscriptable
2024-02-13 23:54:42.509 | ERROR    | __main__:parse_data:95 - error
Traceback (most recent call last):

  File "/mnt/E83C5EC13C5E8A88/projects/go-table-editor/parser/./nb_parser.py", line 104, in <module>
    parse_data()
    └ <function parse_data at 0x7f1048c65760>

> File "/mnt/E83C5EC13C5E8A88/projects/go-table-editor/parser/./nb_parser.py", line 83, in parse_data
    d = dists.get_dist(csrf.lower().strip())
        │     │        │    └ <method 'lower' of 'str' objects>
        │     │        └ ' Abay Residence '
        │     └ <function district_manager.get_dist at 0x7f1049b0fec0>
        └ <districts.district_manager object at 0x7f104b21bfd0>

  File "/mnt/E83C5EC13C5E8A88/projects/go-table-editor/parser/districts.py", line 50, in get_dist
    if a[1] <= 80:
       └ None

TypeError: 'NoneType' object is not subscriptable
2024-02-13 23:55:46.086 | ERROR    | __main__:parse_data:95 - error
Traceback (most recent call last):

  File "/mnt/E83C5EC13C5E8A88/projects/go-table-editor/parser/./nb_parser.py", line 104, in <module>
    parse_data()
    └ <function parse_data at 0x7f212b809760>

> File "/mnt/E83C5EC13C5E8A88/projects/go-table-editor/parser/./nb_parser.py", line 83, in parse_data
    d = dists.get_dist(csrf.lower().strip())
        │     │        │    └ <method 'lower' of 'str' objects>
        │     │        └ ' Abay Residence '
        │     └ <function district_manager.get_dist at 0x7f212c293ec0>
        └ <districts.district_manager object at 0x7f212dd1ffd0>

  File "/mnt/E83C5EC13C5E8A88/projects/go-table-editor/parser/districts.py", line 50, in get_dist
    if a[1] <= 80:
       └ None

TypeError: 'NoneType' object is not subscriptable
2024-02-13 23:58:13.156 | ERROR    | __main__:parse_data:95 - error
Traceback (most recent call last):

  File "/mnt/E83C5EC13C5E8A88/projects/go-table-editor/parser/./nb_parser.py", line 104, in <module>
    parse_data()
    └ <function parse_data at 0x7fae73ca2c00>

> File "/mnt/E83C5EC13C5E8A88/projects/go-table-editor/parser/./nb_parser.py", line 83, in parse_data
    d = dists.get_dist(csrf.lower().strip())
        │     │        │    └ <method 'lower' of 'str' objects>
        │     │        └ ' Abay Residence '
        │     └ <function district_manager.get_dist at 0x7fae74746200>
        └ <districts.district_manager object at 0x7fae7621bfd0>

  File "/mnt/E83C5EC13C5E8A88/projects/go-table-editor/parser/districts.py", line 50, in get_dist
    if a[1] <= 80:
       └ None

TypeError: 'NoneType' object is not subscriptable
